Workbook

Sheet Lines
B3: 黑龙江中 | C3: 黑龙江东 | D3: 黑龙江西 | E3: 吉林南 | F3: 吉林东 | G3: 吉林西 | H3: 吉林中 | I3: 辽中 | J3: 辽西北 | K3: 辽南 | L3: 蒙东南 | M3: 蒙东北 | N3: 陕西北 | O3: 陕西中南 | P3: 甘肃西 | Q3: 甘肃中 | R3: 甘肃南 | S3: 青海 | T3: 宁夏自治区 | U3: 新疆北 | V3: 新疆南 | W3: 西藏自治区 | X3: 河北北 | Y3: 河北南 | Z3: 北京市 | AA3: 天津市 | AB3: 山西省 | AC3: 山东省 | AD3: 蒙西 | AE3: 湖北省 | AF3: 湖南省 | AG3: 江西省 | AH3: 河南省 | AI3: 重庆市 | AJ3: 四川省 | AK3: 广东省 | AL3: 海南省 | AM3: 广西自治区 | AN3: 贵州省 | AO3: 云南省 | AP3: 上海市 | AQ3: 江苏省 | AR3: 安徽省 | AS3: 福建省 | AT3: 浙江省
A4: 黑龙江中 | C4: 500AC*3 | D4: 500AC*3 | H4: 500AC*3,220AC*4
A5: 黑龙江东 | B5: 500AC*3 | F5: 500AC*3,220AC*4 | AV5: 黑龙江与俄罗斯间通过500千伏相连
A6: 黑龙江西 | B6: 500AC*3 | M6: 500AC*2
A7: 吉林南 | F7: 500AC*2 | H7: 500AC*1 | I7: 500AC*2
A8: 吉林东 | C8: 500AC*3,220AC*4 | E8: 500AC*2 | H8: 500AC*1 | M8: 220AC*2
A9: 吉林西 | H9: 500AC*3 | L9: 220AC*3
A10: 吉林中 | B10: 500AC*3,220AC*4 | E10: 500AC*1 | F10: 500AC*1 | G10: 500AC*3 | I10: 500AC*2,220AC*5
A11: 辽中 | E11: 500AC*2 | H11: 500AC*2,220AC*5 | J11: 500AC*6 | K11: 500AC*6 | L11: 500AC*2,220AC*1 | X11: 500AC*2
A12: 辽西北 | I12: 500AC*6 | L12: 500AC*4 | M12: ±500(穆家--伊敏 , 伊穆直流 / 呼辽直流3000MW) | X12: 500AC*3,±500高岭背靠背直流（3000MW）
A13: 辽南 | I13: 500AC*6
A14: 蒙东南 | G14: 220AC*3 | I14: 500AC*2,220AC*1 | J14: 500AC*4
A15: 蒙东北 | D15: 500AC*2 | F15: 220AC*2 | J15: ±500(穆家--伊敏 , 伊穆直流 / 呼辽直流3000MW) | AC15: ±800扎鲁特-山东（10000MW）+2*1000锡盟-山东（4000MW+5000MW） | AQ15: ±800锡盟-江苏（10000MW）+1000锡盟-南京（9400MW）
A16: 陕西北 | O16: 750AC*2, 330AC*2 | X16: 500AC*4 | AB16: 500AC*3 | AC16: 1000榆横-潍坊（7200MW） | AE16: ±800陕西-湖北（10000MW） | AG16: ±800陕北-江西（8000MW） | AH16: 1000（陇彬-豫北5000MW）
A17: 陕西中南 | N17: 750AC*2, 330AC*2 | R17: 750AC*2, 330AC*7 | AB17: 330AC*4 | AH17: 500AC*1, 330AC*2 | AJ17: ±500(德宝直流3000MW)
A18: 甘肃西 | Q18: 750AC*2, 330AC*2 | S18: 750AC*2 | U18: 750AC*4
A19: 甘肃中 | P19: 750AC*2, 330AC*2 | R19: 750AC*2, 330AC*4 | S19: 750AC*4, 330AC*5 | T19: 750AC*2, 330AC*5 | AL19: ±800酒泉-湖南（8000MW） | AQ19: ±800陇东-江苏（10000MW）
A20: 甘肃南 | O20: 750AC*2, 330AC*7 | Q20: 750AC*2, 330AC*4 | T20: 330AC*1
A21: 青海 | P21: 750AC*2 | Q21: 750AC*4, 330AC*5 | AH21: ±800青海-河南（8000MW）
A22: 宁夏自治区 | Q22: 750AC*2, 330AC*5 | R22: 330AC*1 | AC22: ±660(直流 银东4000MW）(~±500kV) | AT22: ±800宁东-浙江（8000MW）
A23: 新疆北 | P23: 750AC*4 | V23: 220AC*1 | AH23: ±800哈密南-郑州(8000MW) | AJ23: ±1100准东-四川成都（12000MW） | AR23: ±1100准东-淮南（12000MW）+±1100昌吉-古泉（12000MW）
A24: 新疆南 | U24: 220AC*1
A25: 西藏自治区
A26: 河北北 | I26: 500AC*2 | J26: 500AC*3,±500高岭背靠背直流（3000MW） | N26: 500AC*4 | Z26: 500AC*9, 1000北京-石家庄（5000MW） | AA26: 500AC*2, 1000（廊坊－海河) | AD26: 500AC*9
A27: 河北南 | Z27: 500AC*4 | AA27: 500AC*4, 1000(海河－保定交流) | AB27: 500AC*13, 220AC*2, 110AC*1, 1000(北岳－保定交流) | AC27: 500AC*4, 1000（山东-河北特高压环网工程4000MW） | AH27: 500AC*1
A28: 北京市 | X28: 500AC*9, 1000北京-石家庄（5000MW） | Y28: 500AC*4 | AA28: 500AC*2 | AB28: 500AC*5
A29: 天津市 | X29: 500AC*2, 1000（廊坊－海河) | Y29: 500AC*4, 1000(海河－保定交流) | Z29: 500AC*2 | AC29: 海河－泉城 交流 | AD29: 1000蒙西-天津南（5000MW）
A30: 山西省 | N30: 500AC*3 | O30: 330AC*4 | Y30: 500AC*13, 220AC*2, 110AC*1, 1000(北岳－保定交流) | Z30: 500AC*5 | AC30: 500AC*3 | AD30: 500AC*4, 1000蒙西-晋中（5000MW） | AE30: 1000(晋东南--南阳--荆门5000MW) | AQ30: 500AC*4, ±800（山西晋北-南京8000MW）
A31: 山东省 | M31: ±800扎鲁特-山东（10000MW）+2*1000锡盟-山东（4000MW+5000MW） | N31: 1000榆横-潍坊（7200MW） | T31: ±660(~±500kV)(直流 银东4000MW） | Y31: 500AC*4, 1000（山东-河北特高压环网工程4000MW） | AA31: 海河－泉城 交流 | AB31: 500AC*3 | AD31: ±800上海庙-山东（10000MW） | AQ31: 500AC*3
A32: 蒙西 | X32: 500AC*9 | AA32: 1000蒙西-天津南（5000MW） | AB32: 500AC*4, 1000蒙西-晋中（5000MW） | AC32: ±800上海庙-山东（10000MW）
A33: 湖北省 | N33: ±800陕西-湖北（10000MW） | AB33: 1000(晋东南--南阳--荆门5000MW) | AF33: 500AC*2 | AG33: 500AC*3 | AH33: 500AC*4 | AI33: 500AC*4 | AJ33: 1000雅安-武汉特高压交流（8000MW） | AK33: ±500(江城直流3000MW) | AP33: 2±500+2±500（3000MW+3000MW） | AQ33: 1*±500
A34: 湖南省 | AE34: 500AC*2 | AK34: 500AC*2, ±500鲤鱼江送南方电网（1900MW） | AN34: 1*500
A35: 江西省 | N35: ±800陕北-江西（8000MW） | AE35: 500AC*3 | AJ35: ±800吉安-金上（10000MW）
A36: 河南省 | N36: 1000（陇彬-豫北5000MW） | O36: 500AC*1, 330AC*2 | S36: ±800青海-河南（8000MW） | U36: ±800哈密南-郑州(8000MW) | Y36: 500AC*1 | AE36: 500AC*4
A37: 重庆市 | AE37: 500AC*4 | AJ37: 500AC*3
A38: 四川省 | O38: ±500(德宝直流3000MW) | U38: ±1100准东-四川成都（12000MW） | AE38: 1000雅安-武汉特高压交流（8000MW） | AG38: ±800吉安-金上（10000MW） | AI38: 500AC*3 | AP38: ±800(复奉线6400MW) | AQ38: ±800锦屏-苏南（7200MW） | AT38: ±800(溪洛渡左岸—浙江金华8000MW)+±500江城直流（3000MW）
A39: 广东省 | AE39: ±500(江城直流3000MW) | AF39: 500AC*2, ±500鲤鱼江送南方电网（1900MW） | AL39: 500AC*1, 220AC*4 | AM39: 500AC*8 | AN39: 500AC*4, ±500(高肇直流3000MW,天广线1800MW,兴安直流3000MW) | AO39: 500AC*4, ±500(2*溪洛渡右岸6400MW)+ ±800(楚穗线5000MW,糯扎渡5000MW)+ ±800（滇西北-广东5000MW）
A40: 海南省 | Q40: ±800酒泉-湖南（8000MW） | AK40: 500AC*1, 220AC*4
A41: 广西自治区 | AK41: 500AC*8 | AN41: 500AC*7, 220AC*8 | AO41: 500AC*4, 220AC*2, ±500（金中直流3200MW）
A42: 贵州省 | AF42: 1*500 | AK42: 500AC*4, ±500(高肇直流3000MW,天广线1800MW,兴安直流3000MW) | AM42: 500AC*7, 220AC*8
...

Sheet 1000
B1: 1000交流
A2: 1000
B3: 黑龙江中 | C3: 黑龙江东 | D3: 黑龙江西 | E3: 吉林南 | F3: 吉林东 | G3: 吉林西 | H3: 吉林中 | I3: 辽中 | J3: 辽西北 | K3: 辽南 | L3: 蒙东南 | M3: 蒙东北 | N3: 陕西北 | O3: 陕西中南 | P3: 甘肃西 | Q3: 甘肃中 | R3: 甘肃南 | S3: 青海 | T3: 宁夏自治区 | U3: 新疆北 | V3: 新疆南 | W3: 西藏自治区 | X3: 河北北 | Y3: 河北南 | Z3: 北京市 | AA3: 天津市 | AB3: 山西省 | AC3: 山东省 | AD3: 蒙西 | AE3: 湖北省 | AF3: 湖南省 | AG3: 江西省 | AH3: 河南省 | AI3: 重庆市 | AJ3: 四川省 | AK3: 广东省 | AL3: 海南省 | AM3: 广西自治区 | AN3: 贵州省 | AO3: 云南省 | AP3: 上海市 | AQ3: 江苏省 | AR3: 安徽省 | AS3: 福建省 | AT3: 浙江省
A4: 黑龙江中 | B4: =IF(ISERROR(FIND($A$2,Lines!B4))=TRUE,"",Lines!B4) | C4: =IF(ISERROR(FIND($A$2,Lines!C4))=TRUE,"",Lines!C4) | D4: =IF(ISERROR(FIND($A$2,Lines!D4))=TRUE,"",Lines!D4) | E4: =IF(ISERROR(FIND($A$2,Lines!E4))=TRUE,"",Lines!E4) | F4: =IF(ISERROR(FIND($A$2,Lines!F4))=TRUE,"",Lines!F4) | G4: =IF(ISERROR(FIND($A$2,Lines!G4))=TRUE,"",Lines!G4) | H4: =IF(ISERROR(FIND($A$2,Lines!H4))=TRUE,"",Lines!H4) | I4: =IF(ISERROR(FIND($A$2,Lines!I4))=TRUE,"",Lines!I4) | ... AT4: =IF(ISERROR(FIND($A$2,Lines!AT4))=TRUE,"",Lines!AT4)
A5: 黑龙江东 | B5: =IF(ISERROR(FIND($A$2,Lines!B5))=TRUE,"",Lines!B5) | C5: =IF(ISERROR(FIND($A$2,Lines!C5))=TRUE,"",Lines!C5) | D5: =IF(ISERROR(FIND($A$2,Lines!D5))=TRUE,"",Lines!D5) | E5: =IF(ISERROR(FIND($A$2,Lines!E5))=TRUE,"",Lines!E5) | F5: =IF(ISERROR(FIND($A$2,Lines!F5))=TRUE,"",Lines!F5) | G5: =IF(ISERROR(FIND($A$2,Lines!G5))=TRUE,"",Lines!G5) | H5: =IF(ISERROR(FIND($A$2,Lines!H5))=TRUE,"",Lines!H5) | I5: =IF(ISERROR(FIND($A$2,Lines!I5))=TRUE,"",Lines!I5) | ... AT5: =IF(ISERROR(FIND($A$2,Lines!AT5))=TRUE,"",Lines!AT5)
A6: 黑龙江西 | B6: =IF(ISERROR(FIND($A$2,Lines!B6))=TRUE,"",Lines!B6) | C6: =IF(ISERROR(FIND($A$2,Lines!C6))=TRUE,"",Lines!C6) | D6: =IF(ISERROR(FIND($A$2,Lines!D6))=TRUE,"",Lines!D6) | E6: =IF(ISERROR(FIND($A$2,Lines!E6))=TRUE,"",Lines!E6) | F6: =IF(ISERROR(FIND($A$2,Lines!F6))=TRUE,"",Lines!F6) | G6: =IF(ISERROR(FIND($A$2,Lines!G6))=TRUE,"",Lines!G6) | H6: =IF(ISERROR(FIND($A$2,Lines!H6))=TRUE,"",Lines!H6) | I6: =IF(ISERROR(FIND($A$2,Lines!I6))=TRUE,"",Lines!I6) | ... AT6: =IF(ISERROR(FIND($A$2,Lines!AT6))=TRUE,"",Lines!AT6)
A7: 吉林南 | B7: =IF(ISERROR(FIND($A$2,Lines!B7))=TRUE,"",Lines!B7) | C7: =IF(ISERROR(FIND($A$2,Lines!C7))=TRUE,"",Lines!C7) | D7: =IF(ISERROR(FIND($A$2,Lines!D7))=TRUE,"",Lines!D7) | E7: =IF(ISERROR(FIND($A$2,Lines!E7))=TRUE,"",Lines!E7) | F7: =IF(ISERROR(FIND($A$2,Lines!F7))=TRUE,"",Lines!F7) | G7: =IF(ISERROR(FIND($A$2,Lines!G7))=TRUE,"",Lines!G7) | H7: =IF(ISERROR(FIND($A$2,Lines!H7))=TRUE,"",Lines!H7) | I7: =IF(ISERROR(FIND($A$2,Lines!I7))=TRUE,"",Lines!I7) | ... AT7: =IF(ISERROR(FIND($A$2,Lines!AT7))=TRUE,"",Lines!AT7)
A8: 吉林东 | B8: =IF(ISERROR(FIND($A$2,Lines!B8))=TRUE,"",Lines!B8) | C8: =IF(ISERROR(FIND($A$2,Lines!C8))=TRUE,"",Lines!C8) | D8: =IF(ISERROR(FIND($A$2,Lines!D8))=TRUE,"",Lines!D8) | E8: =IF(ISERROR(FIND($A$2,Lines!E8))=TRUE,"",Lines!E8) | F8: =IF(ISERROR(FIND($A$2,Lines!F8))=TRUE,"",Lines!F8) | G8: =IF(ISERROR(FIND($A$2,Lines!G8))=TRUE,"",Lines!G8) | H8: =IF(ISERROR(FIND($A$2,Lines!H8))=TRUE,"",Lines!H8) | I8: =IF(ISERROR(FIND($A$2,Lines!I8))=TRUE,"",Lines!I8) | ... AT8: =IF(ISERROR(FIND($A$2,Lines!AT8))=TRUE,"",Lines!AT8)
A9: 吉林西 | B9: =IF(ISERROR(FIND($A$2,Lines!B9))=TRUE,"",Lines!B9) | C9: =IF(ISERROR(FIND($A$2,Lines!C9))=TRUE,"",Lines!C9) | D9: =IF(ISERROR(FIND($A$2,Lines!D9))=TRUE,"",Lines!D9) | E9: =IF(ISERROR(FIND($A$2,Lines!E9))=TRUE,"",Lines!E9) | F9: =IF(ISERROR(FIND($A$2,Lines!F9))=TRUE,"",Lines!F9) | G9: =IF(ISERROR(FIND($A$2,Lines!G9))=TRUE,"",Lines!G9) | H9: =IF(ISERROR(FIND($A$2,Lines!H9))=TRUE,"",Lines!H9) | I9: =IF(ISERROR(FIND($A$2,Lines!I9))=TRUE,"",Lines!I9) | ... AT9: =IF(ISERROR(FIND($A$2,Lines!AT9))=TRUE,"",Lines!AT9)
A10: 吉林中 | B10: =IF(ISERROR(FIND($A$2,Lines!B10))=TRUE,"",Lines!B10) | C10: =IF(ISERROR(FIND($A$2,Lines!C10))=TRUE,"",Lines!C10) | D10: =IF(ISERROR(FIND($A$2,Lines!D10))=TRUE,"",Lines!D10) | E10: =IF(ISERROR(FIND($A$2,Lines!E10))=TRUE,"",Lines!E10) | F10: =IF(ISERROR(FIND($A$2,Lines!F10))=TRUE,"",Lines!F10) | G10: =IF(ISERROR(FIND($A$2,Lines!G10))=TRUE,"",Lines!G10) | H10: =IF(ISERROR(FIND($A$2,Lines!H10))=TRUE,"",Lines!H10) | I10: =IF(ISERROR(FIND($A$2,Lines!I10))=TRUE,"",Lines!I10) | ... AT10: =IF(ISERROR(FIND($A$2,Lines!AT10))=TRUE,"",Lines!AT10)
A11: 辽中 | B11: =IF(ISERROR(FIND($A$2,Lines!B11))=TRUE,"",Lines!B11) | C11: =IF(ISERROR(FIND($A$2,Lines!C11))=TRUE,"",Lines!C11) | D11: =IF(ISERROR(FIND($A$2,Lines!D11))=TRUE,"",Lines!D11) | E11: =IF(ISERROR(FIND($A$2,Lines!E11))=TRUE,"",Lines!E11) | F11: =IF(ISERROR(FIND($A$2,Lines!F11))=TRUE,"",Lines!F11) | G11: =IF(ISERROR(FIND($A$2,Lines!G11))=TRUE,"",Lines!G11) | H11: =IF(ISERROR(FIND($A$2,Lines!H11))=TRUE,"",Lines!H11) | I11: =IF(ISERROR(FIND($A$2,Lines!I11))=TRUE,"",Lines!I11) | ... AT11: =IF(ISERROR(FIND($A$2,Lines!AT11))=TRUE,"",Lines!AT11)
A12: 辽西北 | B12: =IF(ISERROR(FIND($A$2,Lines!B12))=TRUE,"",Lines!B12) | C12: =IF(ISERROR(FIND($A$2,Lines!C12))=TRUE,"",Lines!C12) | D12: =IF(ISERROR(FIND($A$2,Lines!D12))=TRUE,"",Lines!D12) | E12: =IF(ISERROR(FIND($A$2,Lines!E12))=TRUE,"",Lines!E12) | F12: =IF(ISERROR(FIND($A$2,Lines!F12))=TRUE,"",Lines!F12) | G12: =IF(ISERROR(FIND($A$2,Lines!G12))=TRUE,"",Lines!G12) | H12: =IF(ISERROR(FIND($A$2,Lines!H12))=TRUE,"",Lines!H12) | I12: =IF(ISERROR(FIND($A$2,Lines!I12))=TRUE,"",Lines!I12) | ... AT12: =IF(ISERROR(FIND($A$2,Lines!AT12))=TRUE,"",Lines!AT12)
A13: 辽南 | B13: =IF(ISERROR(FIND($A$2,Lines!B13))=TRUE,"",Lines!B13) | C13: =IF(ISERROR(FIND($A$2,Lines!C13))=TRUE,"",Lines!C13) | D13: =IF(ISERROR(FIND($A$2,Lines!D13))=TRUE,"",Lines!D13) | E13: =IF(ISERROR(FIND($A$2,Lines!E13))=TRUE,"",Lines!E13) | F13: =IF(ISERROR(FIND($A$2,Lines!F13))=TRUE,"",Lines!F13) | G13: =IF(ISERROR(FIND($A$2,Lines!G13))=TRUE,"",Lines!G13) | H13: =IF(ISERROR(FIND($A$2,Lines!H13))=TRUE,"",Lines!H13) | I13: =IF(ISERROR(FIND($A$2,Lines!I13))=TRUE,"",Lines!I13) | ... AT13: =IF(ISERROR(FIND($A$2,Lines!AT13))=TRUE,"",Lines!AT13)
A14: 蒙东南 | B14: =IF(ISERROR(FIND($A$2,Lines!B14))=TRUE,"",Lines!B14) | C14: =IF(ISERROR(FIND($A$2,Lines!C14))=TRUE,"",Lines!C14) | D14: =IF(ISERROR(FIND($A$2,Lines!D14))=TRUE,"",Lines!D14) | E14: =IF(ISERROR(FIND($A$2,Lines!E14))=TRUE,"",Lines!E14) | F14: =IF(ISERROR(FIND($A$2,Lines!F14))=TRUE,"",Lines!F14) | G14: =IF(ISERROR(FIND($A$2,Lines!G14))=TRUE,"",Lines!G14) | H14: =IF(ISERROR(FIND($A$2,Lines!H14))=TRUE,"",Lines!H14) | I14: =IF(ISERROR(FIND($A$2,Lines!I14))=TRUE,"",Lines!I14) | ... AT14: =IF(ISERROR(FIND($A$2,Lines!AT14))=TRUE,"",Lines!AT14)
A15: 蒙东北 | B15: =IF(ISERROR(FIND($A$2,Lines!B15))=TRUE,"",Lines!B15) | C15: =IF(ISERROR(FIND($A$2,Lines!C15))=TRUE,"",Lines!C15) | D15: =IF(ISERROR(FIND($A$2,Lines!D15))=TRUE,"",Lines!D15) | E15: =IF(ISERROR(FIND($A$2,Lines!E15))=TRUE,"",Lines!E15) | F15: =IF(ISERROR(FIND($A$2,Lines!F15))=TRUE,"",Lines!F15) | G15: =IF(ISERROR(FIND($A$2,Lines!G15))=TRUE,"",Lines!G15) | H15: =IF(ISERROR(FIND($A$2,Lines!H15))=TRUE,"",Lines!H15) | I15: =IF(ISERROR(FIND($A$2,Lines!I15))=TRUE,"",Lines!I15) | ... AT15: =IF(ISERROR(FIND($A$2,Lines!AT15))=TRUE,"",Lines!AT15)
A16: 陕西北 | B16: =IF(ISERROR(FIND($A$2,Lines!B16))=TRUE,"",Lines!B16) | C16: =IF(ISERROR(FIND($A$2,Lines!C16))=TRUE,"",Lines!C16) | D16: =IF(ISERROR(FIND($A$2,Lines!D16))=TRUE,"",Lines!D16) | E16: =IF(ISERROR(FIND($A$2,Lines!E16))=TRUE,"",Lines!E16) | F16: =IF(ISERROR(FIND($A$2,Lines!F16))=TRUE,"",Lines!F16) | G16: =IF(ISERROR(FIND($A$2,Lines!G16))=TRUE,"",Lines!G16) | H16: =IF(ISERROR(FIND($A$2,Lines!H16))=TRUE,"",Lines!H16) | I16: =IF(ISERROR(FIND($A$2,Lines!I16))=TRUE,"",Lines!I16) | ... AA16: =IF(ISERROR(FIND($A$2,Lines!AA16))=TRUE,"",Lines!AA16) | AB16: =IF(ISERROR(FIND($A$2,Lines!#REF!))=TRUE,"",Lines!#REF!) | AC16: =IF(ISERROR(FIND($A$2,Lines!AC16))=TRUE,"",Lines!AC16) -> 1000榆横-潍坊（7200MW） | AD16: =IF(ISERROR(FIND($A$2,Lines!AD16))=TRUE,"",Lines!AD16) | AE16: =IF(ISERROR(FIND($A$2,Lines!AE16))=TRUE,"",Lines!AE16) -> ±800陕西-湖北（10000MW） | AF16: =IF(ISERROR(FIND($A$2,Lines!AF16))=TRUE,"",Lines!AF16) | AG16: =IF(ISERROR(FIND($A$2,Lines!AG16))=TRUE,"",Lines!AG16) | AH16: =IF(ISERROR(FIND($A$2,Lines!AH16))=TRUE,"",Lines!AH16) -> 1000（陇彬-豫北5000MW） | AI16: =IF(ISERROR(FIND($A$2,Lines!AI16))=TRUE,"",Lines!AI16) | AJ16: =IF(ISERROR(FIND($A$2,Lines!AJ16))=TRUE,"",Lines!AJ16) | ... AT16: =IF(ISERROR(FIND($A$2,Lines!AT16))=TRUE,"",Lines!AT16)
A17: 陕西中南 | B17: =IF(ISERROR(FIND($A$2,Lines!B17))=TRUE,"",Lines!B17) | C17: =IF(ISERROR(FIND($A$2,Lines!C17))=TRUE,"",Lines!C17) | D17: =IF(ISERROR(FIND($A$2,Lines!D17))=TRUE,"",Lines!D17) | E17: =IF(ISERROR(FIND($A$2,Lines!E17))=TRUE,"",Lines!E17) | F17: =IF(ISERROR(FIND($A$2,Lines!F17))=TRUE,"",Lines!F17) | G17: =IF(ISERROR(FIND($A$2,Lines!G17))=TRUE,"",Lines!G17) | H17: =IF(ISERROR(FIND($A$2,Lines!H17))=TRUE,"",Lines!H17) | I17: =IF(ISERROR(FIND($A$2,Lines!I17))=TRUE,"",Lines!I17) | ... Z17: =IF(ISERROR(FIND($A$2,Lines!Z17))=TRUE,"",Lines!Z17) | AA17: =IF(ISERROR(FIND($A$2,Lines!AB16))=TRUE,"",Lines!AB16) | AB17: =IF(ISERROR(FIND($A$2,Lines!AB17))=TRUE,"",Lines!AB17) | AC17: =IF(ISERROR(FIND($A$2,Lines!AC17))=TRUE,"",Lines!AC17) | AD17: =IF(ISERROR(FIND($A$2,Lines!AD17))=TRUE,"",Lines!AD17) | AE17: =IF(ISERROR(FIND($A$2,Lines!AE17))=TRUE,"",Lines!AE17) | AF17: =IF(ISERROR(FIND($A$2,Lines!AF17))=TRUE,"",Lines!AF17) | AG17: =IF(ISERROR(FIND($A$2,Lines!AG17))=TRUE,"",Lines!AG17) | AH17: =IF(ISERROR(FIND($A$2,Lines!AH17))=TRUE,"",Lines!AH17) | AI17: =IF(ISERROR(FIND($A$2,Lines!AI17))=TRUE,"",Lines!AI17) | ... AT17: =IF(ISERROR(FIND($A$2,Lines!AT17))=TRUE,"",Lines!AT17)
A18: 甘肃西 | B18: =IF(ISERROR(FIND($A$2,Lines!B18))=TRUE,"",Lines!B18) | C18: =IF(ISERROR(FIND($A$2,Lines!C18))=TRUE,"",Lines!C18) | D18: =IF(ISERROR(FIND($A$2,Lines!D18))=TRUE,"",Lines!D18) | E18: =IF(ISERROR(FIND($A$2,Lines!E18))=TRUE,"",Lines!E18) | F18: =IF(ISERROR(FIND($A$2,Lines!F18))=TRUE,"",Lines!F18) | G18: =IF(ISERROR(FIND($A$2,Lines!G18))=TRUE,"",Lines!G18) | H18: =IF(ISERROR(FIND($A$2,Lines!H18))=TRUE,"",Lines!H18) | I18: =IF(ISERROR(FIND($A$2,Lines!I18))=TRUE,"",Lines!I18) | ... AT18: =IF(ISERROR(FIND($A$2,Lines!AT18))=TRUE,"",Lines!AT18)
A19: 甘肃中 | B19: =IF(ISERROR(FIND($A$2,Lines!B19))=TRUE,"",Lines!B19) | C19: =IF(ISERROR(FIND($A$2,Lines!C19))=TRUE,"",Lines!C19) | D19: =IF(ISERROR(FIND($A$2,Lines!D19))=TRUE,"",Lines!D19) | E19: =IF(ISERROR(FIND($A$2,Lines!E19))=TRUE,"",Lines!E19) | F19: =IF(ISERROR(FIND($A$2,Lines!F19))=TRUE,"",Lines!F19) | G19: =IF(ISERROR(FIND($A$2,Lines!G19))=TRUE,"",Lines!G19) | H19: =IF(ISERROR(FIND($A$2,Lines!H19))=TRUE,"",Lines!H19) | I19: =IF(ISERROR(FIND($A$2,Lines!I19))=TRUE,"",Lines!I19) | ... AT19: =IF(ISERROR(FIND($A$2,Lines!AT19))=TRUE,"",Lines!AT19)
A20: 甘肃南 | B20: =IF(ISERROR(FIND($A$2,Lines!B20))=TRUE,"",Lines!B20) | C20: =IF(ISERROR(FIND($A$2,Lines!C20))=TRUE,"",Lines!C20) | D20: =IF(ISERROR(FIND($A$2,Lines!D20))=TRUE,"",Lines!D20) | E20: =IF(ISERROR(FIND($A$2,Lines!E20))=TRUE,"",Lines!E20) | F20: =IF(ISERROR(FIND($A$2,Lines!F20))=TRUE,"",Lines!F20) | G20: =IF(ISERROR(FIND($A$2,Lines!G20))=TRUE,"",Lines!G20) | H20: =IF(ISERROR(FIND($A$2,Lines!H20))=TRUE,"",Lines!H20) | I20: =IF(ISERROR(FIND($A$2,Lines!I20))=TRUE,"",Lines!I20) | ... AT20: =IF(ISERROR(FIND($A$2,Lines!AT20))=TRUE,"",Lines!AT20)
A21: 青海 | B21: =IF(ISERROR(FIND($A$2,Lines!B21))=TRUE,"",Lines!B21) | C21: =IF(ISERROR(FIND($A$2,Lines!C21))=TRUE,"",Lines!C21) | D21: =IF(ISERROR(FIND($A$2,Lines!D21))=TRUE,"",Lines!D21) | E21: =IF(ISERROR(FIND($A$2,Lines!E21))=TRUE,"",Lines!E21) | F21: =IF(ISERROR(FIND($A$2,Lines!F21))=TRUE,"",Lines!F21) | G21: =IF(ISERROR(FIND($A$2,Lines!G21))=TRUE,"",Lines!G21) | H21: =IF(ISERROR(FIND($A$2,Lines!H21))=TRUE,"",Lines!H21) | I21: =IF(ISERROR(FIND($A$2,Lines!I21))=TRUE,"",Lines!I21) | ... AT21: =IF(ISERROR(FIND($A$2,Lines!AT21))=TRUE,"",Lines!AT21)
A22: 宁夏自治区 | B22: =IF(ISERROR(FIND($A$2,Lines!B22))=TRUE,"",Lines!B22) | C22: =IF(ISERROR(FIND($A$2,Lines!C22))=TRUE,"",Lines!C22) | D22: =IF(ISERROR(FIND($A$2,Lines!D22))=TRUE,"",Lines!D22) | E22: =IF(ISERROR(FIND($A$2,Lines!E22))=TRUE,"",Lines!E22) | F22: =IF(ISERROR(FIND($A$2,Lines!F22))=TRUE,"",Lines!F22) | G22: =IF(ISERROR(FIND($A$2,Lines!G22))=TRUE,"",Lines!G22) | H22: =IF(ISERROR(FIND($A$2,Lines!H22))=TRUE,"",Lines!H22) | I22: =IF(ISERROR(FIND($A$2,Lines!I22))=TRUE,"",Lines!I22) | ... AT22: =IF(ISERROR(FIND($A$2,Lines!AT22))=TRUE,"",Lines!AT22)
A23: 新疆北 | B23: =IF(ISERROR(FIND($A$2,Lines!B23))=TRUE,"",Lines!B23) | C23: =IF(ISERROR(FIND($A$2,Lines!C23))=TRUE,"",Lines!C23) | D23: =IF(ISERROR(FIND($A$2,Lines!D23))=TRUE,"",Lines!D23) | E23: =IF(ISERROR(FIND($A$2,Lines!E23))=TRUE,"",Lines!E23) | F23: =IF(ISERROR(FIND($A$2,Lines!F23))=TRUE,"",Lines!F23) | G23: =IF(ISERROR(FIND($A$2,Lines!G23))=TRUE,"",Lines!G23) | H23: =IF(ISERROR(FIND($A$2,Lines!H23))=TRUE,"",Lines!H23) | I23: =IF(ISERROR(FIND($A$2,Lines!I23))=TRUE,"",Lines!I23) | ... AT23: =IF(ISERROR(FIND($A$2,Lines!AT23))=TRUE,"",Lines!AT23)
A24: 新疆南 | B24: =IF(ISERROR(FIND($A$2,Lines!B24))=TRUE,"",Lines!B24) | C24: =IF(ISERROR(FIND($A$2,Lines!C24))=TRUE,"",Lines!C24) | D24: =IF(ISERROR(FIND($A$2,Lines!D24))=TRUE,"",Lines!D24) | E24: =IF(ISERROR(FIND($A$2,Lines!E24))=TRUE,"",Lines!E24) | F24: =IF(ISERROR(FIND($A$2,Lines!F24))=TRUE,"",Lines!F24) | G24: =IF(ISERROR(FIND($A$2,Lines!G24))=TRUE,"",Lines!G24) | H24: =IF(ISERROR(FIND($A$2,Lines!H24))=TRUE,"",Lines!H24) | I24: =IF(ISERROR(FIND($A$2,Lines!I24))=TRUE,"",Lines!I24) | ... AT24: =IF(ISERROR(FIND($A$2,Lines!AT24))=TRUE,"",Lines!AT24)
A25: 西藏自治区 | B25: =IF(ISERROR(FIND($A$2,Lines!B25))=TRUE,"",Lines!B25) | C25: =IF(ISERROR(FIND($A$2,Lines!C25))=TRUE,"",Lines!C25) | D25: =IF(ISERROR(FIND($A$2,Lines!D25))=TRUE,"",Lines!D25) | E25: =IF(ISERROR(FIND($A$2,Lines!E25))=TRUE,"",Lines!E25) | F25: =IF(ISERROR(FIND($A$2,Lines!F25))=TRUE,"",Lines!F25) | G25: =IF(ISERROR(FIND($A$2,Lines!G25))=TRUE,"",Lines!G25) | H25: =IF(ISERROR(FIND($A$2,Lines!H25))=TRUE,"",Lines!H25) | I25: =IF(ISERROR(FIND($A$2,Lines!I25))=TRUE,"",Lines!I25) | ... AT25: =IF(ISERROR(FIND($A$2,Lines!AT25))=TRUE,"",Lines!AT25)
A26: 河北北 | B26: =IF(ISERROR(FIND($A$2,Lines!B26))=TRUE,"",Lines!B26) | C26: =IF(ISERROR(FIND($A$2,Lines!C26))=TRUE,"",Lines!C26) | D26: =IF(ISERROR(FIND($A$2,Lines!D26))=TRUE,"",Lines!D26) | E26: =IF(ISERROR(FIND($A$2,Lines!E26))=TRUE,"",Lines!E26) | F26: =IF(ISERROR(FIND($A$2,Lines!F26))=TRUE,"",Lines!F26) | G26: =IF(ISERROR(FIND($A$2,Lines!G26))=TRUE,"",Lines!G26) | H26: =IF(ISERROR(FIND($A$2,Lines!H26))=TRUE,"",Lines!H26) | I26: =IF(ISERROR(FIND($A$2,Lines!I26))=TRUE,"",Lines!I26) | ... AT26: =IF(ISERROR(FIND($A$2,Lines!AT26))=TRUE,"",Lines!AT26)
A27: 河北南 | B27: =IF(ISERROR(FIND($A$2,Lines!B27))=TRUE,"",Lines!B27) | C27: =IF(ISERROR(FIND($A$2,Lines!C27))=TRUE,"",Lines!C27) | D27: =IF(ISERROR(FIND($A$2,Lines!D27))=TRUE,"",Lines!D27) | E27: =IF(ISERROR(FIND($A$2,Lines!E27))=TRUE,"",Lines!E27) | F27: =IF(ISERROR(FIND($A$2,Lines!F27))=TRUE,"",Lines!F27) | G27: =IF(ISERROR(FIND($A$2,Lines!G27))=TRUE,"",Lines!G27) | H27: =IF(ISERROR(FIND($A$2,Lines!H27))=TRUE,"",Lines!H27) | I27: =IF(ISERROR(FIND($A$2,Lines!I27))=TRUE,"",Lines!I27) | ... AT27: =IF(ISERROR(FIND($A$2,Lines!AT27))=TRUE,"",Lines!AT27)
A28: 北京市 | B28: =IF(ISERROR(FIND($A$2,Lines!B28))=TRUE,"",Lines!B28) | C28: =IF(ISERROR(FIND($A$2,Lines!C28))=TRUE,"",Lines!C28) | D28: =IF(ISERROR(FIND($A$2,Lines!D28))=TRUE,"",Lines!D28) | E28: =IF(ISERROR(FIND($A$2,Lines!E28))=TRUE,"",Lines!E28) | F28: =IF(ISERROR(FIND($A$2,Lines!F28))=TRUE,"",Lines!F28) | G28: =IF(ISERROR(FIND($A$2,Lines!G28))=TRUE,"",Lines!G28) | H28: =IF(ISERROR(FIND($A$2,Lines!H28))=TRUE,"",Lines!H28) | I28: =IF(ISERROR(FIND($A$2,Lines!I28))=TRUE,"",Lines!I28) | ... AT28: =IF(ISERROR(FIND($A$2,Lines!AT28))=TRUE,"",Lines!AT28)
A29: 天津市 | B29: =IF(ISERROR(FIND($A$2,Lines!B29))=TRUE,"",Lines!B29) | C29: =IF(ISERROR(FIND($A$2,Lines!C29))=TRUE,"",Lines!C29) | D29: =IF(ISERROR(FIND($A$2,Lines!D29))=TRUE,"",Lines!D29) | E29: =IF(ISERROR(FIND($A$2,Lines!E29))=TRUE,"",Lines!E29) | F29: =IF(ISERROR(FIND($A$2,Lines!F29))=TRUE,"",Lines!F29) | G29: =IF(ISERROR(FIND($A$2,Lines!G29))=TRUE,"",Lines!G29) | H29: =IF(ISERROR(FIND($A$2,Lines!H29))=TRUE,"",Lines!H29) | I29: =IF(ISERROR(FIND($A$2,Lines!I29))=TRUE,"",Lines!I29) | ... AT29: =IF(ISERROR(FIND($A$2,Lines!AT29))=TRUE,"",Lines!AT29)
... A48: 浙江省 | B48: =IF(ISERROR(FIND($A$2,Lines!B48))=TRUE,"",Lines!B48) | C48: =IF(ISERROR(FIND($A$2,Lines!C48))=TRUE,"",Lines!C48) | D48: =IF(ISERROR(FIND($A$2,Lines!D48))=TRUE,"",Lines!D48) | E48: =IF(ISERROR(FIND($A$2,Lines!E48))=TRUE,"",Lines!E48) | F48: =IF(ISERROR(FIND($A$2,Lines!F48))=TRUE,"",Lines!F48) | G48: =IF(ISERROR(FIND($A$2,Lines!G48))=TRUE,"",Lines!G48) | H48: =IF(ISERROR(FIND($A$2,Lines!H48))=TRUE,"",Lines!H48) | I48: =IF(ISERROR(FIND($A$2,Lines!I48))=TRUE,"",Lines!I48) | ... AT48: =IF(ISERROR(FIND($A$2,Lines!AT48))=TRUE,"",Lines!AT48)
B51: 测算参数
B52: 电压等级 | C52: 典型额定容量（万kW）
B53: 750kV | C53: 180
B54: 500kV | C54: 120
B55: 330kV | C55: 40
B56: 220kV | C56: 20
B57: ±500kV直流 | C57: 300

Sheet 750
A2: 750AC | B2: 0.9 | C2: (Actually: 1.8 per line, bc twin all lines)
B3: 黑龙江中 | C3: 黑龙江东 | D3: 黑龙江西 | E3: 吉林南 | F3: 吉林东 | G3: 吉林西 | H3: 吉林中 | I3: 辽中 | J3: 辽西北 | K3: 辽南 | L3: 蒙东南 | M3: 蒙东北 | N3: 陕西北 | O3: 陕西中南 | P3: 甘肃西 | Q3: 甘肃中 | R3: 甘肃南 | S3: 青海 | T3: 宁夏自治区 | U3: 新疆北 | V3: 新疆南 | W3: 西藏自治区 | X3: 河北北 | Y3: 河北南 | Z3: 北京市 | AA3: 天津市 | AB3: 山西省 | AC3: 山东省 | AD3: 蒙西 | AE3: 湖北省 | AF3: 湖南省 | AG3: 江西省 | AH3: 河南省 | AI3: 重庆市 | AJ3: 四川省 | AK3: 广东省 | AL3: 海南省 | AM3: 广西自治区 | AN3: 贵州省 | AO3: 云南省 | AP3: 上海市 | AQ3: 江苏省 | AR3: 安徽省 | AS3: 福建省 | AT3: 浙江省
A4: 黑龙江中 | B4: =IF(ISERROR(FIND($A$2,Lines!B4))=TRUE,"",MID(Lines!B4,FIND($A$2,Lines!B4)+LEN($A$2)+1,FIND(",",_xlfn.CONCAT(Lines!B4,","),FIND($A$2,Lines!B4))-FIND($A$2,Lines!B4)-LEN($A$2)-1)) | C4: =IF(ISERROR(FIND($A$2,Lines!C4))=TRUE,"",MID(Lines!C4,FIND($A$2,Lines!C4)+LEN($A$2)+1,FIND(",",_xlfn.CONCAT(Lines!C4,","),FIND($A$2,Lines!C4))-FIND($A$2,Lines!C4)-LEN($A$2)-1)) | D4: =IF(ISERROR(FIND($A$2,Lines!D4))=TRUE,"",MID(Lines!D4,FIND($A$2,Lines!D4)+LEN($A$2)+1,FIND(",",_xlfn.CONCAT(Lines!D4,","),FIND($A$2,Lines!D4))-FIND($A$2,Lines!D4)-LEN($A$2)-1)) | E4: =IF(ISERROR(FIND($A$2,Lines!E4))=TRUE,"",MID(Lines!E4,FIND($A$2,Lines!E4)+LEN($A$2)+1,FIND(",",_xlfn.CONCAT(Lines!E4,","),FIND($A$2,Lines!E4))-FIND($A$2,Lines!E4)-LEN($A$2)-1)) | F4: =IF(ISERROR(FIND($A$2,Lines!F4))=TRUE,"",MID(Lines!F4,FIND($A$2,Lines!F4)+LEN($A$2)+1,FIND(",",_xlfn.CONCAT(Lines!F4,","),FIND($A$2,Lines!F4))-FIND($A$2,Lines!F4)-LEN($A$2)-1)) | G4: =IF(ISERROR(FIND($A$2,Lines!G4))=TRUE,"",MID(Lines!G4,FIND($A$2,Lines!G4)+LEN($A$2)+1,FIND(",",_xlfn.CONCAT(Lines!G4,","),FIND($A$2,Lines!G4))-FIND($A$2,Lines!G4)-LEN($A$2)-1)) | H4: =IF(ISERROR(FIND($A$2,Lines!H4))=TRUE,"",MID(Lines!H4,FIND($A$2,Lines!H4)+LEN($A$2)+1,FIND(",",_xlfn.CONCAT(Lines!H4,","),FIND($A$2,Lines!H4))-FIND($A$2,Lines!H4)-LEN($A$2)-1)) | I4: =IF(ISERROR(FIND($A$2,Lines!I4))=TRUE,"",MID(Lines!I4,FIND($A$2,Lines!I4)+LEN($A$2)+1,FIND(",",_xlfn.CONCAT(Lines!I4,","),FIND($A$2,Lines!I4))-FIND($A$2,Lines!I4)-LEN($A$2)-1)) | ... AT4: =IF(ISERROR(FIND($A$2,Lines!AT4))=TRUE,"",MID(Lines!AT4,FIND($A$2,Lines!AT4)+LEN($A$2)+1,FIND(",",_xlfn.CONCAT(Lines!AT4,","),FIND($A$2,Lines!AT4))-FIND($A$2,Lines!AT4)-LEN($A$2)-1))
A5: 黑龙江东 | B5: =IF(ISERROR(FIND($A$2,Lines!B5))=TRUE,"",MID(Lines!B5,FIND($A$2,Lines!B5)+LEN($A$2)+1,FIND(",",_xlfn.CONCAT(Lines!B5,","),FIND($A$2,Lines!B5))-FIND($A$2,Lines!B5)-LEN($A$2)-1)) | C5: =IF(ISERROR(FIND($A$2,Lines!C5))=TRUE,"",MID(Lines!C5,FIND($A$2,Lines!C5)+LEN($A$2)+1,FIND(",",_xlfn.CONCAT(Lines!C5,","),FIND($A$2,Lines!C5))-FIND($A$2,Lines!C5)-LEN($A$2)-1)) | D5: =IF(ISERROR(FIND($A$2,Lines!D5))=TRUE,"",MID(Lines!D5,FIND($A$2,Lines!D5)+LEN($A$2)+1,FIND(",",_xlfn.CONCAT(Lines!D5,","),FIND($A$2,Lines!D5))-FIND($A$2,Lines!D5)-LEN($A$2)-1)) | E5: =IF(ISERROR(FIND($A$2,Lines!E5))=TRUE,"",MID(Lines!E5,FIND($A$2,Lines!E5)+LEN($A$2)+1,FIND(",",_xlfn.CONCAT(Lines!E5,","),FIND($A$2,Lines!E5))-FIND($A$2,Lines!E5)-LEN($A$2)-1)) | F5: =IF(ISERROR(FIND($A$2,Lines!F5))=TRUE,"",MID(Lines!F5,FIND($A$2,Lines!F5)+LEN($A$2)+1,FIND(",",_xlfn.CONCAT(Lines!F5,","),FIND($A$2,Lines!F5))-FIND($A$2,Lines!F5)-LEN($A$2)-1)) | G5: =IF(ISERROR(FIND($A$2,Lines!G5))=TRUE,"",MID(Lines!G5,FIND($A$2,Lines!G5)+LEN($A$2)+1,FIND(",",_xlfn.CONCAT(Lines!G5,","),FIND($A$2,Lines!G5))-FIND($A$2,Lines!G5)-LEN($A$2)-1)) | H5: =IF(ISERROR(FIND($A$2,Lines!H5))=TRUE,"",MID(Lines!H5,FIND($A$2,Lines!H5)+LEN($A$2)+1,FIND(",",_xlfn.CONCAT(Lines!H5,","),FIND($A$2,Lines!H5))-FIND($A$2,Lines!H5)-LEN($A$2)-1)) | I5: =IF(ISERROR(FIND($A$2,Lines!I5))=TRUE,"",MID(Lines!I5,FIND($A$2,Lines!I5)+LEN($A$2)+1,FIND(",",_xlfn.CONCAT(Lines!I5,","),FIND($A$2,Lines!I5))-FIND($A$2,Lines!I5)-LEN($A$2)-1)) | ... AT5: =IF(ISERROR(FIND($A$2,Lines!AT5))=TRUE,"",MID(Lines!AT5,FIND($A$2,Lines!AT5)+LEN($A$2)+1,FIND(",",_xlfn.CONCAT(Lines!AT5,","),FIND($A$2,Lines!AT5))-FIND($A$2,Lines!AT5)-LEN($A$2)-1))
A6: 黑龙江西 | B6: =IF(ISERROR(FIND($A$2,Lines!B6))=TRUE,"",MID(Lines!B6,FIND($A$2,Lines!B6)+LEN($A$2)+1,FIND(",",_xlfn.CONCAT(Lines!B6,","),FIND($A$2,Lines!B6))-FIND($A$2,Lines!B6)-LEN($A$2)-1)) | C6: =IF(ISERROR(FIND($A$2,Lines!C6))=TRUE,"",MID(Lines!C6,FIND($A$2,Lines!C6)+LEN($A$2)+1,FIND(",",_xlfn.CONCAT(Lines!C6,","),FIND($A$2,Lines!C6))-FIND($A$2,Lines!C6)-LEN($A$2)-1)) | D6: =IF(ISERROR(FIND($A$2,Lines!D6))=TRUE,"",MID(Lines!D6,FIND($A$2,Lines!D6)+LEN($A$2)+1,FIND(",",_xlfn.CONCAT(Lines!D6,","),FIND($A$2,Lines!D6))-FIND($A$2,Lines!D6)-LEN($A$2)-1)) | E6: =IF(ISERROR(FIND($A$2,Lines!E6))=TRUE,"",MID(Lines!E6,FIND($A$2,Lines!E6)+LEN($A$2)+1,FIND(",",_xlfn.CONCAT(Lines!E6,","),FIND($A$2,Lines!E6))-FIND($A$2,Lines!E6)-LEN($A$2)-1)) | F6: =IF(ISERROR(FIND($A$2,Lines!F6))=TRUE,"",MID(Lines!F6,FIND($A$2,Lines!F6)+LEN($A$2)+1,FIND(",",_xlfn.CONCAT(Lines!F6,","),FIND($A$2,Lines!F6))-FIND($A$2,Lines!F6)-LEN($A$2)-1)) | G6: =IF(ISERROR(FIND($A$2,Lines!G6))=TRUE,"",MID(Lines!G6,FIND($A$2,Lines!G6)+LEN($A$2)+1,FIND(",",_xlfn.CONCAT(Lines!G6,","),FIND($A$2,Lines!G6))-FIND($A$2,Lines!G6)-LEN($A$2)-1)) | H6: =IF(ISERROR(FIND($A$2,Lines!H6))=TRUE,"",MID(Lines!H6,FIND($A$2,Lines!H6)+LEN($A$2)+1,FIND(",",_xlfn.CONCAT(Lines!H6,","),FIND($A$2,Lines!H6))-FIND($A$2,Lines!H6)-LEN($A$2)-1)) | I6: =IF(ISERROR(FIND($A$2,Lines!I6))=TRUE,"",MID(Lines!I6,FIND($A$2,Lines!I6)+LEN($A$2)+1,FIND(",",_xlfn.CONCAT(Lines!I6,","),FIND($A$2,Lines!I6))-FIND($A$2,Lines!I6)-LEN($A$2)-1)) | ... AT6: =IF(ISERROR(FIND($A$2,Lines!AT6))=TRUE,"",MID(Lines!AT6,FIND($A$2,Lines!AT6)+LEN($A$2)+1,FIND(",",_xlfn.CONCAT(Lines!AT6,","),FIND($A$2,Lines!AT6))-FIND($A$2,Lines!AT6)-LEN($A$2)-1))
A7: 吉林南 | B7: =IF(ISERROR(FIND($A$2,Lines!B7))=TRUE,"",MID(Lines!B7,FIND($A$2,Lines!B7)+LEN($A$2)+1,FIND(",",_xlfn.CONCAT(Lines!B7,","),FIND($A$2,Lines!B7))-FIND($A$2,Lines!B7)-LEN($A$2)-1)) | C7: =IF(ISERROR(FIND($A$2,Lines!C7))=TRUE,"",MID(Lines!C7,FIND($A$2,Lines!C7)+LEN($A$2)+1,FIND(",",_xlfn.CONCAT(Lines!C7,","),FIND($A$2,Lines!C7))-FIND($A$2,Lines!C7)-LEN($A$2)-1)) | D7: =IF(ISERROR(FIND($A$2,Lines!D7))=TRUE,"",MID(Lines!D7,FIND($A$2,Lines!D7)+LEN($A$2)+1,FIND(",",_xlfn.CONCAT(Lines!D7,","),FIND($A$2,Lines!D7))-FIND($A$2,Lines!D7)-LEN($A$2)-1)) | E7: =IF(ISERROR(FIND($A$2,Lines!E7))=TRUE,"",MID(Lines!E7,FIND($A$2,Lines!E7)+LEN($A$2)+1,FIND(",",_xlfn.CONCAT(Lines!E7,","),FIND($A$2,Lines!E7))-FIND($A$2,Lines!E7)-LEN($A$2)-1)) | F7: =IF(ISERROR(FIND($A$2,Lines!F7))=TRUE,"",MID(Lines!F7,FIND($A$2,Lines!F7)+LEN($A$2)+1,FIND(",",_xlfn.CONCAT(Lines!F7,","),FIND($A$2,Lines!F7))-FIND($A$2,Lines!F7)-LEN($A$2)-1)) | G7: =IF(ISERROR(FIND($A$2,Lines!G7))=TRUE,"",MID(Lines!G7,FIND($A$2,Lines!G7)+LEN($A$2)+1,FIND(",",_xlfn.CONCAT(Lines!G7,","),FIND($A$2,Lines!G7))-FIND($A$2,Lines!G7)-LEN($A$2)-1)) | H7: =IF(ISERROR(FIND($A$2,Lines!H7))=TRUE,"",MID(Lines!H7,FIND($A$2,Lines!H7)+LEN($A$2)+1,FIND(",",_xlfn.CONCAT(Lines!H7,","),FIND($A$2,Lines!H7))-FIND($A$2,Lines!H7)-LEN($A$2)-1)) | I7: =IF(ISERROR(FIND($A$2,Lines!I7))=TRUE,"",MID(Lines!I7,FIND($A$2,Lines!I7)+LEN($A$2)+1,FIND(",",_xlfn.CONCAT(Lines!I7,","),FIND($A$2,Lines!I7))-FIND($A$2,Lines!I7)-LEN($A$2)-1)) | ... AT7: =IF(ISERROR(FIND($A$2,Lines!AT7))=TRUE,"",MID(Lines!AT7,FIND($A$2,Lines!AT7)+LEN($A$2)+1,FIND(",",_xlfn.CONCAT(Lines!AT7,","),FIND($A$2,Lines!AT7))-FIND($A$2,Lines!AT7)-LEN($A$2)-1))
A8: 吉林东 | B8: =IF(ISERROR(FIND($A$2,Lines!B8))=TRUE,"",MID(Lines!B8,FIND($A$2,Lines!B8)+LEN($A$2)+1,FIND(",",_xlfn.CONCAT(Lines!B8,","),FIND($A$2,Lines!B8))-FIND($A$2,Lines!B8)-LEN($A$2)-1)) | C8: =IF(ISERROR(FIND($A$2,Lines!C8))=TRUE,"",MID(Lines!C8,FIND($A$2,Lines!C8)+LEN($A$2)+1,FIND(",",_xlfn.CONCAT(Lines!C8,","),FIND($A$2,Lines!C8))-FIND($A$2,Lines!C8)-LEN($A$2)-1)) | D8: =IF(ISERROR(FIND($A$2,Lines!D8))=TRUE,"",MID(Lines!D8,FIND($A$2,Lines!D8)+LEN($A$2)+1,FIND(",",_xlfn.CONCAT(Lines!D8,","),FIND($A$2,Lines!D8))-FIND($A$2,Lines!D8)-LEN($A$2)-1)) | E8: =IF(ISERROR(FIND($A$2,Lines!E8))=TRUE,"",MID(Lines!E8,FIND($A$2,Lines!E8)+LEN($A$2)+1,FIND(",",_xlfn.CONCAT(Lines!E8,","),FIND($A$2,Lines!E8))-FIND($A$2,Lines!E8)-LEN($A$2)-1)) | F8: =IF(ISERROR(FIND($A$2,Lines!F8))=TRUE,"",MID(Lines!F8,FIND($A$2,Lines!F8)+LEN($A$2)+1,FIND(",",_xlfn.CONCAT(Lines!F8,","),FIND($A$2,Lines!F8))-FIND($A$2,Lines!F8)-LEN($A$2)-1)) | G8: =IF(ISERROR(FIND($A$2,Lines!G8))=TRUE,"",MID(Lines!G8,FIND($A$2,Lines!G8)+LEN($A$2)+1,FIND(",",_xlfn.CONCAT(Lines!G8,","),FIND($A$2,Lines!G8))-FIND($A$2,Lines!G8)-LEN($A$2)-1)) | H8: =IF(ISERROR(FIND($A$2,Lines!H8))=TRUE,"",MID(Lines!H8,FIND($A$2,Lines!H8)+LEN($A$2)+1,FIND(",",_xlfn.CONCAT(Lines!H8,","),FIND($A$2,Lines!H8))-FIND($A$2,Lines!H8)-LEN($A$2)-1)) | I8: =IF(ISERROR(FIND($A$2,Lines!I8))=TRUE,"",MID(Lines!I8,FIND($A$2,Lines!I8)+LEN($A$2)+1,FIND(",",_xlfn.CONCAT(Lines!I8,","),FIND($A$2,Lines!I8))-FIND($A$2,Lines!I8)-LEN($A$2)-1)) | ... AT8: =IF(ISERROR(FIND($A$2,Lines!AT8))=TRUE,"",MID(Lines!AT8,FIND($A$2,Lines!AT8)+LEN($A$2)+1,FIND(",",_xlfn.CONCAT(Lines!AT8,","),FIND($A$2,Lines!AT8))-FIND($A$2,Lines!AT8)-LEN($A$2)-1))
A9: 吉林西 | B9: =IF(ISERROR(FIND($A$2,Lines!B9))=TRUE,"",MID(Lines!B9,FIND($A$2,Lines!B9)+LEN($A$2)+1,FIND(",",_xlfn.CONCAT(Lines!B9,","),FIND($A$2,Lines!B9))-FIND($A$2,Lines!B9)-LEN($A$2)-1)) | C9: =IF(ISERROR(FIND($A$2,Lines!C9))=TRUE,"",MID(Lines!C9,FIND($A$2,Lines!C9)+LEN($A$2)+1,FIND(",",_xlfn.CONCAT(Lines!C9,","),FIND($A$2,Lines!C9))-FIND($A$2,Lines!C9)-LEN($A$2)-1)) | D9: =IF(ISERROR(FIND($A$2,Lines!D9))=TRUE,"",MID(Lines!D9,FIND($A$2,Lines!D9)+LEN($A$2)+1,FIND(",",_xlfn.CONCAT(Lines!D9,","),FIND($A$2,Lines!D9))-FIND($A$2,Lines!D9)-LEN($A$2)-1)) | E9: =IF(ISERROR(FIND($A$2,Lines!E9))=TRUE,"",MID(Lines!E9,FIND($A$2,Lines!E9)+LEN($A$2)+1,FIND(",",_xlfn.CONCAT(Lines!E9,","),FIND($A$2,Lines!E9))-FIND($A$2,Lines!E9)-LEN($A$2)-1)) | F9: =IF(ISERROR(FIND($A$2,Lines!F9))=TRUE,"",MID(Lines!F9,FIND($A$2,Lines!F9)+LEN($A$2)+1,FIND(",",_xlfn.CONCAT(Lines!F9,","),FIND($A$2,Lines!F9))-FIND($A$2,Lines!F9)-LEN($A$2)-1)) | G9: =IF(ISERROR(FIND($A$2,Lines!G9))=TRUE,"",MID(Lines!G9,FIND($A$2,Lines!G9)+LEN($A$2)+1,FIND(",",_xlfn.CONCAT(Lines!G9,","),FIND($A$2,Lines!G9))-FIND($A$2,Lines!G9)-LEN($A$2)-1)) | H9: =IF(ISERROR(FIND($A$2,Lines!H9))=TRUE,"",MID(Lines!H9,FIND($A$2,Lines!H9)+LEN($A$2)+1,FIND(",",_xlfn.CONCAT(Lines!H9,","),FIND($A$2,Lines!H9))-FIND($A$2,Lines!H9)-LEN($A$2)-1)) | I9: =IF(ISERROR(FIND($A$2,Lines!I9))=TRUE,"",MID(Lines!I9,FIND($A$2,Lines!I9)+LEN($A$2)+1,FIND(",",_xlfn.CONCAT(Lines!I9,","),FIND($A$2,Lines!I9))-FIND($A$2,Lines!I9)-LEN($A$2)-1)) | ... AT9: =IF(ISERROR(FIND($A$2,Lines!AT9))=TRUE,"",MID(Lines!AT9,FIND($A$2,Lines!AT9)+LEN($A$2)+1,FIND(",",_xlfn.CONCAT(Lines!AT9,","),FIND($A$2,Lines!AT9))-FIND($A$2,Lines!AT9)-LEN($A$2)-1))
A10: 吉林中 | B10: =IF(ISERROR(FIND($A$2,Lines!B10))=TRUE,"",MID(Lines!B10,FIND($A$2,Lines!B10)+LEN($A$2)+1,FIND(",",_xlfn.CONCAT(Lines!B10,","),FIND($A$2,Lines!B10))-FIND($A$2,Lines!B10)-LEN($A$2)-1)) | C10: =IF(ISERROR(FIND($A$2,Lines!C10))=TRUE,"",MID(Lines!C10,FIND($A$2,Lines!C10)+LEN($A$2)+1,FIND(",",_xlfn.CONCAT(Lines!C10,","),FIND($A$2,Lines!C10))-FIND($A$2,Lines!C10)-LEN($A$2)-1)) | D10: =IF(ISERROR(FIND($A$2,Lines!D10))=TRUE,"",MID(Lines!D10,FIND($A$2,Lines!D10)+LEN($A$2)+1,FIND(",",_xlfn.CONCAT(Lines!D10,","),FIND($A$2,Lines!D10))-FIND($A$2,Lines!D10)-LEN($A$2)-1)) | E10: =IF(ISERROR(FIND($A$2,Lines!E10))=TRUE,"",MID(Lines!E10,FIND($A$2,Lines!E10)+LEN($A$2)+1,FIND(",",_xlfn.CONCAT(Lines!E10,","),FIND($A$2,Lines!E10))-FIND($A$2,Lines!E10)-LEN($A$2)-1)) | F10: =IF(ISERROR(FIND($A$2,Lines!F10))=TRUE,"",MID(Lines!F10,FIND($A$2,Lines!F10)+LEN($A$2)+1,FIND(",",_xlfn.CONCAT(Lines!F10,","),FIND($A$2,Lines!F10))-FIND($A$2,Lines!F10)-LEN($A$2)-1)) | G10: =IF(ISERROR(FIND($A$2,Lines!G10))=TRUE,"",MID(Lines!G10,FIND($A$2,Lines!G10)+LEN($A$2)+1,FIND(",",_xlfn.CONCAT(Lines!G10,","),FIND($A$2,Lines!G10))-FIND($A$2,Lines!G10)-LEN($A$2)-1)) | H10: =IF(ISERROR(FIND($A$2,Lines!H10))=TRUE,"",MID(Lines!H10,FIND($A$2,Lines!H10)+LEN($A$2)+1,FIND(",",_xlfn.CONCAT(Lines!H10,","),FIND($A$2,Lines!H10))-FIND($A$2,Lines!H10)-LEN($A$2)-1)) | I10: =IF(ISERROR(FIND($A$2,Lines!I10))=TRUE,"",MID(Lines!I10,FIND($A$2,Lines!I10)+LEN($A$2)+1,FIND(",",_xlfn.CONCAT(Lines!I10,","),FIND($A$2,Lines!I10))-FIND($A$2,Lines!I10)-LEN($A$2)-1)) | ... AT10: =IF(ISERROR(FIND($A$2,Lines!AT10))=TRUE,"",MID(Lines!AT10,FIND($A$2,Lines!AT10)+LEN($A$2)+1,FIND(",",_xlfn.CONCAT(Lines!AT10,","),FIND($A$2,Lines!AT10))-FIND($A$2,Lines!AT10)-LEN($A$2)-1))
A11: 辽中 | B11: =IF(ISERROR(FIND($A$2,Lines!B11))=TRUE,"",MID(Lines!B11,FIND($A$2,Lines!B11)+LEN($A$2)+1,FIND(",",_xlfn.CONCAT(Lines!B11,","),FIND($A$2,Lines!B11))-FIND($A$2,Lines!B11)-LEN($A$2)-1)) | C11: =IF(ISERROR(FIND($A$2,Lines!C11))=TRUE,"",MID(Lines!C11,FIND($A$2,Lines!C11)+LEN($A$2)+1,FIND(",",_xlfn.CONCAT(Lines!C11,","),FIND($A$2,Lines!C11))-FIND($A$2,Lines!C11)-LEN($A$2)-1)) | D11: =IF(ISERROR(FIND($A$2,Lines!D11))=TRUE,"",MID(Lines!D11,FIND($A$2,Lines!D11)+LEN($A$2)+1,FIND(",",_xlfn.CONCAT(Lines!D11,","),FIND($A$2,Lines!D11))-FIND($A$2,Lines!D11)-LEN($A$2)-1)) | E11: =IF(ISERROR(FIND($A$2,Lines!E11))=TRUE,"",MID(Lines!E11,FIND($A$2,Lines!E11)+LEN($A$2)+1,FIND(",",_xlfn.CONCAT(Lines!E11,","),FIND($A$2,Lines!E11))-FIND($A$2,Lines!E11)-LEN($A$2)-1)) | F11: =IF(ISERROR(FIND($A$2,Lines!F11))=TRUE,"",MID(Lines!F11,FIND($A$2,Lines!F11)+LEN($A$2)+1,FIND(",",_xlfn.CONCAT(Lines!F11,","),FIND($A$2,Lines!F11))-FIND($A$2,Lines!F11)-LEN($A$2)-1)) | G11: =IF(ISERROR(FIND($A$2,Lines!G11))=TRUE,"",MID(Lines!G11,FIND($A$2,Lines!G11)+LEN($A$2)+1,FIND(",",_xlfn.CONCAT(Lines!G11,","),FIND($A$2,Lines!G11))-FIND($A$2,Lines!G11)-LEN($A$2)-1)) | H11: =IF(ISERROR(FIND($A$2,Lines!H11))=TRUE,"",MID(Lines!H11,FIND($A$2,Lines!H11)+LEN($A$2)+1,FIND(",",_xlfn.CONCAT(Lines!H11,","),FIND($A$2,Lines!H11))-FIND($A$2,Lines!H11)-LEN($A$2)-1)) | I11: =IF(ISERROR(FIND($A$2,Lines!I11))=TRUE,"",MID(Lines!I11,FIND($A$2,Lines!I11)+LEN($A$2)+1,FIND(",",_xlfn.CONCAT(Lines!I11,","),FIND($A$2,Lines!I11))-FIND($A$2,Lines!I11)-LEN($A$2)-1)) | ... AT11: =IF(ISERROR(FIND($A$2,Lines!AT11))=TRUE,"",MID(Lines!AT11,FIND($A$2,Lines!AT11)+LEN($A$2)+1,FIND(",",_xlfn.CONCAT(Lines!AT11,","),FIND($A$2,Lines!AT11))-FIND($A$2,Lines!AT11)-LEN($A$2)-1))
A12: 辽西北 | B12: =IF(ISERROR(FIND($A$2,Lines!B12))=TRUE,"",MID(Lines!B12,FIND($A$2,Lines!B12)+LEN($A$2)+1,FIND(",",_xlfn.CONCAT(Lines!B12,","),FIND($A$2,Lines!B12))-FIND($A$2,Lines!B12)-LEN($A$2)-1)) | C12: =IF(ISERROR(FIND($A$2,Lines!C12))=TRUE,"",MID(Lines!C12,FIND($A$2,Lines!C12)+LEN($A$2)+1,FIND(",",_xlfn.CONCAT(Lines!C12,","),FIND($A$2,Lines!C12))-FIND($A$2,Lines!C12)-LEN($A$2)-1)) | D12: =IF(ISERROR(FIND($A$2,Lines!D12))=TRUE,"",MID(Lines!D12,FIND($A$2,Lines!D12)+LEN($A$2)+1,FIND(",",_xlfn.CONCAT(Lines!D12,","),FIND($A$2,Lines!D12))-FIND($A$2,Lines!D12)-LEN($A$2)-1)) | E12: =IF(ISERROR(FIND($A$2,Lines!E12))=TRUE,"",MID(Lines!E12,FIND($A$2,Lines!E12)+LEN($A$2)+1,FIND(",",_xlfn.CONCAT(Lines!E12,","),FIND($A$2,Lines!E12))-FIND($A$2,Lines!E12)-LEN($A$2)-1)) | F12: =IF(ISERROR(FIND($A$2,Lines!F12))=TRUE,"",MID(Lines!F12,FIND($A$2,Lines!F12)+LEN($A$2)+1,FIND(",",_xlfn.CONCAT(Lines!F12,","),FIND($A$2,Lines!F12))-FIND($A$2,Lines!F12)-LEN($A$2)-1)) | G12: =IF(ISERROR(FIND($A$2,Lines!G12))=TRUE,"",MID(Lines!G12,FIND($A$2,Lines!G12)+LEN($A$2)+1,FIND(",",_xlfn.CONCAT(Lines!G12,","),FIND($A$2,Lines!G12))-FIND($A$2,Lines!G12)-LEN($A$2)-1)) | H12: =IF(ISERROR(FIND($A$2,Lines!H12))=TRUE,"",MID(Lines!H12,FIND($A$2,Lines!H12)+LEN($A$2)+1,FIND(",",_xlfn.CONCAT(Lines!H12,","),FIND($A$2,Lines!H12))-FIND($A$2,Lines!H12)-LEN($A$2)-1)) | I12: =IF(ISERROR(FIND($A$2,Lines!I12))=TRUE,"",MID(Lines!I12,FIND($A$2,Lines!I12)+LEN($A$2)+1,FIND(",",_xlfn.CONCAT(Lines!I12,","),FIND($A$2,Lines!I12))-FIND($A$2,Lines!I12)-LEN($A$2)-1)) | ... AT12: =IF(ISERROR(FIND($A$2,Lines!AT12))=TRUE,"",MID(Lines!AT12,FIND($A$2,Lines!AT12)+LEN($A$2)+1,FIND(",",_xlfn.CONCAT(Lines!AT12,","),FIND($A$2,Lines!AT12))-FIND($A$2,Lines!AT12)-LEN($A$2)-1))
A13: 辽南 | B13: =IF(ISERROR(FIND($A$2,Lines!B13))=TRUE,"",MID(Lines!B13,FIND($A$2,Lines!B13)+LEN($A$2)+1,FIND(",",_xlfn.CONCAT(Lines!B13,","),FIND($A$2,Lines!B13))-FIND($A$2,Lines!B13)-LEN($A$2)-1)) | C13: =IF(ISERROR(FIND($A$2,Lines!C13))=TRUE,"",MID(Lines!C13,FIND($A$2,Lines!C13)+LEN($A$2)+1,FIND(",",_xlfn.CONCAT(Lines!C13,","),FIND($A$2,Lines!C13))-FIND($A$2,Lines!C13)-LEN($A$2)-1)) | D13: =IF(ISERROR(FIND($A$2,Lines!D13))=TRUE,"",MID(Lines!D13,FIND($A$2,Lines!D13)+LEN($A$2)+1,FIND(",",_xlfn.CONCAT(Lines!D13,","),FIND($A$2,Lines!D13))-FIND($A$2,Lines!D13)-LEN($A$2)-1)) | E13: =IF(ISERROR(FIND($A$2,Lines!E13))=TRUE,"",MID(Lines!E13,FIND($A$2,Lines!E13)+LEN($A$2)+1,FIND(",",_xlfn.CONCAT(Lines!E13,","),FIND($A$2,Lines!E13))-FIND($A$2,Lines!E13)-LEN($A$2)-1)) | F13: =IF(ISERROR(FIND($A$2,Lines!F13))=TRUE,"",MID(Lines!F13,FIND($A$2,Lines!F13)+LEN($A$2)+1,FIND(",",_xlfn.CONCAT(Lines!F13,","),FIND($A$2,Lines!F13))-FIND($A$2,Lines!F13)-LEN($A$2)-1)) | G13: =IF(ISERROR(FIND($A$2,Lines!G13))=TRUE,"",MID(Lines!G13,FIND($A$2,Lines!G13)+LEN($A$2)+1,FIND(",",_xlfn.CONCAT(Lines!G13,","),FIND($A$2,Lines!G13))-FIND($A$2,Lines!G13)-LEN($A$2)-1)) | H13: =IF(ISERROR(FIND($A$2,Lines!H13))=TRUE,"",MID(Lines!H13,FIND($A$2,Lines!H13)+LEN($A$2)+1,FIND(",",_xlfn.CONCAT(Lines!H13,","),FIND($A$2,Lines!H13))-FIND($A$2,Lines!H13)-LEN($A$2)-1)) | I13: =IF(ISERROR(FIND($A$2,Lines!I13))=TRUE,"",MID(Lines!I13,FIND($A$2,Lines!I13)+LEN($A$2)+1,FIND(",",_xlfn.CONCAT(Lines!I13,","),FIND($A$2,Lines!I13))-FIND($A$2,Lines!I13)-LEN($A$2)-1)) | ... AT13: =IF(ISERROR(FIND($A$2,Lines!AT13))=TRUE,"",MID(Lines!AT13,FIND($A$2,Lines!AT13)+LEN($A$2)+1,FIND(",",_xlfn.CONCAT(Lines!AT13,","),FIND($A$2,Lines!AT13))-FIND($A$2,Lines!AT13)-LEN($A$2)-1))
A14: 蒙东南 | B14: =IF(ISERROR(FIND($A$2,Lines!B14))=TRUE,"",MID(Lines!B14,FIND($A$2,Lines!B14)+LEN($A$2)+1,FIND(",",_xlfn.CONCAT(Lines!B14,","),FIND($A$2,Lines!B14))-FIND($A$2,Lines!B14)-LEN($A$2)-1)) | C14: =IF(ISERROR(FIND($A$2,Lines!C14))=TRUE,"",MID(Lines!C14,FIND($A$2,Lines!C14)+LEN($A$2)+1,FIND(",",_xlfn.CONCAT(Lines!C14,","),FIND($A$2,Lines!C14))-FIND($A$2,Lines!C14)-LEN($A$2)-1)) | D14: =IF(ISERROR(FIND($A$2,Lines!D14))=TRUE,"",MID(Lines!D14,FIND($A$2,Lines!D14)+LEN($A$2)+1,FIND(",",_xlfn.CONCAT(Lines!D14,","),FIND($A$2,Lines!D14))-FIND($A$2,Lines!D14)-LEN($A$2)-1)) | E14: =IF(ISERROR(FIND($A$2,Lines!E14))=TRUE,"",MID(Lines!E14,FIND($A$2,Lines!E14)+LEN($A$2)+1,FIND(",",_xlfn.CONCAT(Lines!E14,","),FIND($A$2,Lines!E14))-FIND($A$2,Lines!E14)-LEN($A$2)-1)) | F14: =IF(ISERROR(FIND($A$2,Lines!F14))=TRUE,"",MID(Lines!F14,FIND($A$2,Lines!F14)+LEN($A$2)+1,FIND(",",_xlfn.CONCAT(Lines!F14,","),FIND($A$2,Lines!F14))-FIND($A$2,Lines!F14)-LEN($A$2)-1)) | G14: =IF(ISERROR(FIND($A$2,Lines!G14))=TRUE,"",MID(Lines!G14,FIND($A$2,Lines!G14)+LEN($A$2)+1,FIND(",",_xlfn.CONCAT(Lines!G14,","),FIND($A$2,Lines!G14))-FIND($A$2,Lines!G14)-LEN($A$2)-1)) | H14: =IF(ISERROR(FIND($A$2,Lines!H14))=TRUE,"",MID(Lines!H14,FIND($A$2,Lines!H14)+LEN($A$2)+1,FIND(",",_xlfn.CONCAT(Lines!H14,","),FIND($A$2,Lines!H14))-FIND($A$2,Lines!H14)-LEN($A$2)-1)) | I14: =IF(ISERROR(FIND($A$2,Lines!I14))=TRUE,"",MID(Lines!I14,FIND($A$2,Lines!I14)+LEN($A$2)+1,FIND(",",_xlfn.CONCAT(Lines!I14,","),FIND($A$2,Lines!I14))-FIND($A$2,Lines!I14)-LEN($A$2)-1)) | ... AT14: =IF(ISERROR(FIND($A$2,Lines!AT14))=TRUE,"",MID(Lines!AT14,FIND($A$2,Lines!AT14)+LEN($A$2)+1,FIND(",",_xlfn.CONCAT(Lines!AT14,","),FIND($A$2,Lines!AT14))-FIND($A$2,Lines!AT14)-LEN($A$2)-1))
A15: 蒙东北 | B15: =IF(ISERROR(FIND($A$2,Lines!B15))=TRUE,"",MID(Lines!B15,FIND($A$2,Lines!B15)+LEN($A$2)+1,FIND(",",_xlfn.CONCAT(Lines!B15,","),FIND($A$2,Lines!B15))-FIND($A$2,Lines!B15)-LEN($A$2)-1)) | C15: =IF(ISERROR(FIND($A$2,Lines!C15))=TRUE,"",MID(Lines!C15,FIND($A$2,Lines!C15)+LEN($A$2)+1,FIND(",",_xlfn.CONCAT(Lines!C15,","),FIND($A$2,Lines!C15))-FIND($A$2,Lines!C15)-LEN($A$2)-1)) | D15: =IF(ISERROR(FIND($A$2,Lines!D15))=TRUE,"",MID(Lines!D15,FIND($A$2,Lines!D15)+LEN($A$2)+1,FIND(",",_xlfn.CONCAT(Lines!D15,","),FIND($A$2,Lines!D15))-FIND($A$2,Lines!D15)-LEN($A$2)-1)) | E15: =IF(ISERROR(FIND($A$2,Lines!E15))=TRUE,"",MID(Lines!E15,FIND($A$2,Lines!E15)+LEN($A$2)+1,FIND(",",_xlfn.CONCAT(Lines!E15,","),FIND($A$2,Lines!E15))-FIND($A$2,Lines!E15)-LEN($A$2)-1)) | F15: =IF(ISERROR(FIND($A$2,Lines!F15))=TRUE,"",MID(Lines!F15,FIND($A$2,Lines!F15)+LEN($A$2)+1,FIND(",",_xlfn.CONCAT(Lines!F15,","),FIND($A$2,Lines!F15))-FIND($A$2,Lines!F15)-LEN($A$2)-1)) | G15: =IF(ISERROR(FIND($A$2,Lines!G15))=TRUE,"",MID(Lines!G15,FIND($A$2,Lines!G15)+LEN($A$2)+1,FIND(",",_xlfn.CONCAT(Lines!G15,","),FIND($A$2,Lines!G15))-FIND($A$2,Lines!G15)-LEN($A$2)-1)) | H15: =IF(ISERROR(FIND($A$2,Lines!H15))=TRUE,"",MID(Lines!H15,FIND($A$2,Lines!H15)+LEN($A$2)+1,FIND(",",_xlfn.CONCAT(Lines!H15,","),FIND($A$2,Lines!H15))-FIND($A$2,Lines!H15)-LEN($A$2)-1)) | I15: =IF(ISERROR(FIND($A$2,Lines!I15))=TRUE,"",MID(Lines!I15,FIND($A$2,Lines!I15)+LEN($A$2)+1,FIND(",",_xlfn.CONCAT(Lines!I15,","),FIND($A$2,Lines!I15))-FIND($A$2,Lines!I15)-LEN($A$2)-1)) | ... AT15: =IF(ISERROR(FIND($A$2,Lines!AT15))=TRUE,"",MID(Lines!AT15,FIND($A$2,Lines!AT15)+LEN($A$2)+1,FIND(",",_xlfn.CONCAT(Lines!AT15,","),FIND($A$2,Lines!AT15))-FIND($A$2,Lines!AT15)-LEN($A$2)-1))
A16: 陕西北 | B16: =IF(ISERROR(FIND($A$2,Lines!B16))=TRUE,"",MID(Lines!B16,FIND($A$2,Lines!B16)+LEN($A$2)+1,FIND(",",_xlfn.CONCAT(Lines!B16,","),FIND($A$2,Lines!B16))-FIND($A$2,Lines!B16)-LEN($A$2)-1)) | C16: =IF(ISERROR(FIND($A$2,Lines!C16))=TRUE,"",MID(Lines!C16,FIND($A$2,Lines!C16)+LEN($A$2)+1,FIND(",",_xlfn.CONCAT(Lines!C16,","),FIND($A$2,Lines!C16))-FIND($A$2,Lines!C16)-LEN($A$2)-1)) | D16: =IF(ISERROR(FIND($A$2,Lines!D16))=TRUE,"",MID(Lines!D16,FIND($A$2,Lines!D16)+LEN($A$2)+1,FIND(",",_xlfn.CONCAT(Lines!D16,","),FIND($A$2,Lines!D16))-FIND($A$2,Lines!D16)-LEN($A$2)-1)) | E16: =IF(ISERROR(FIND($A$2,Lines!E16))=TRUE,"",MID(Lines!E16,FIND($A$2,Lines!E16)+LEN($A$2)+1,FIND(",",_xlfn.CONCAT(Lines!E16,","),FIND($A$2,Lines!E16))-FIND($A$2,Lines!E16)-LEN($A$2)-1)) | F16: =IF(ISERROR(FIND($A$2,Lines!F16))=TRUE,"",MID(Lines!F16,FIND($A$2,Lines!F16)+LEN($A$2)+1,FIND(",",_xlfn.CONCAT(Lines!F16,","),FIND($A$2,Lines!F16))-FIND($A$2,Lines!F16)-LEN($A$2)-1)) | G16: =IF(ISERROR(FIND($A$2,Lines!G16))=TRUE,"",MID(Lines!G16,FIND($A$2,Lines!G16)+LEN($A$2)+1,FIND(",",_xlfn.CONCAT(Lines!G16,","),FIND($A$2,Lines!G16))-FIND($A$2,Lines!G16)-LEN($A$2)-1)) | H16: =IF(ISERROR(FIND($A$2,Lines!H16))=TRUE,"",MID(Lines!H16,FIND($A$2,Lines!H16)+LEN($A$2)+1,FIND(",",_xlfn.CONCAT(Lines!H16,","),FIND($A$2,Lines!H16))-FIND($A$2,Lines!H16)-LEN($A$2)-1)) | I16: =IF(ISERROR(FIND($A$2,Lines!I16))=TRUE,"",MID(Lines!I16,FIND($A$2,Lines!I16)+LEN($A$2)+1,FIND(",",_xlfn.CONCAT(Lines!I16,","),FIND($A$2,Lines!I16))-FIND($A$2,Lines!I16)-LEN($A$2)-1)) | ... AA16: =IF(ISERROR(FIND($A$2,Lines!AA16))=TRUE,"",MID(Lines!AA16,FIND($A$2,Lines!AA16)+LEN($A$2)+1,FIND(",",_xlfn.CONCAT(Lines!AA16,","),FIND($A$2,Lines!AA16))-FIND($A$2,Lines!AA16)-LEN($A$2)-1)) | AB16: =IF(ISERROR(FIND($A$2,Lines!#REF!))=TRUE,"",MID(Lines!#REF!,FIND($A$2,Lines!#REF!)+LEN($A$2)+1,FIND(",",_xlfn.CONCAT(Lines!#REF!,","),FIND($A$2,Lines!#REF!))-FIND($A$2,Lines!#REF!)-LEN($A$2)-1)) | AC16: =IF(ISERROR(FIND($A$2,Lines!AC16))=TRUE,"",MID(Lines!AC16,FIND($A$2,Lines!AC16)+LEN($A$2)+1,FIND(",",_xlfn.CONCAT(Lines!AC16,","),FIND($A$2,Lines!AC16))-FIND($A$2,Lines!AC16)-LEN($A$2)-1)) | AD16: =IF(ISERROR(FIND($A$2,Lines!AD16))=TRUE,"",MID(Lines!AD16,FIND($A$2,Lines!AD16)+LEN($A$2)+1,FIND(",",_xlfn.CONCAT(Lines!AD16,","),FIND($A$2,Lines!AD16))-FIND($A$2,Lines!AD16)-LEN($A$2)-1)) | AE16: =IF(ISERROR(FIND($A$2,Lines!AE16))=TRUE,"",MID(Lines!AE16,FIND($A$2,Lines!AE16)+LEN($A$2)+1,FIND(",",_xlfn.CONCAT(Lines!AE16,","),FIND($A$2,Lines!AE16))-FIND($A$2,Lines!AE16)-LEN($A$2)-1)) | AF16: =IF(ISERROR(FIND($A$2,Lines!AF16))=TRUE,"",MID(Lines!AF16,FIND($A$2,Lines!AF16)+LEN($A$2)+1,FIND(",",_xlfn.CONCAT(Lines!AF16,","),FIND($A$2,Lines!AF16))-FIND($A$2,Lines!AF16)-LEN($A$2)-1)) | AG16: =IF(ISERROR(FIND($A$2,Lines!AG16))=TRUE,"",MID(Lines!AG16,FIND($A$2,Lines!AG16)+LEN($A$2)+1,FIND(",",_xlfn.CONCAT(Lines!AG16,","),FIND($A$2,Lines!AG16))-FIND($A$2,Lines!AG16)-LEN($A$2)-1)) | AH16: =IF(ISERROR(FIND($A$2,Lines!AH16))=TRUE,"",MID(Lines!AH16,FIND($A$2,Lines!AH16)+LEN($A$2)+1,FIND(",",_xlfn.CONCAT(Lines!AH16,","),FIND($A$2,Lines!AH16))-FIND($A$2,Lines!AH16)-LEN($A$2)-1)) | AI16: =IF(ISERROR(FIND($A$2,Lines!AI16))=TRUE,"",MID(Lines!AI16,FIND($A$2,Lines!AI16)+LEN($A$2)+1,FIND(",",_xlfn.CONCAT(Lines!AI16,","),FIND($A$2,Lines!AI16))-FIND($A$2,Lines!AI16)-LEN($A$2)-1)) | AJ16: =IF(ISERROR(FIND($A$2,Lines!AJ16))=TRUE,"",MID(Lines!AJ16,FIND($A$2,Lines!AJ16)+LEN($A$2)+1,FIND(",",_xlfn.CONCAT(Lines!AJ16,","),FIND($A$2,Lines!AJ16))-FIND($A$2,Lines!AJ16)-LEN($A$2)-1)) | ... AT16: =IF(ISERROR(FIND($A$2,Lines!AT16))=TRUE,"",MID(Lines!AT16,FIND($A$2,Lines!AT16)+LEN($A$2)+1,FIND(",",_xlfn.CONCAT(Lines!AT16,","),FIND($A$2,Lines!AT16))-FIND($A$2,Lines!AT16)-LEN($A$2)-1))
A17: 陕西中南 | B17: =IF(ISERROR(FIND($A$2,Lines!B17))=TRUE,"",MID(Lines!B17,FIND($A$2,Lines!B17)+LEN($A$2)+1,FIND(",",_xlfn.CONCAT(Lines!B17,","),FIND($A$2,Lines!B17))-FIND($A$2,Lines!B17)-LEN($A$2)-1)) | C17: =IF(ISERROR(FIND($A$2,Lines!C17))=TRUE,"",MID(Lines!C17,FIND($A$2,Lines!C17)+LEN($A$2)+1,FIND(",",_xlfn.CONCAT(Lines!C17,","),FIND($A$2,Lines!C17))-FIND($A$2,Lines!C17)-LEN($A$2)-1)) | D17: =IF(ISERROR(FIND($A$2,Lines!D17))=TRUE,"",MID(Lines!D17,FIND($A$2,Lines!D17)+LEN($A$2)+1,FIND(",",_xlfn.CONCAT(Lines!D17,","),FIND($A$2,Lines!D17))-FIND($A$2,Lines!D17)-LEN($A$2)-1)) | E17: =IF(ISERROR(FIND($A$2,Lines!E17))=TRUE,"",MID(Lines!E17,FIND($A$2,Lines!E17)+LEN($A$2)+1,FIND(",",_xlfn.CONCAT(Lines!E17,","),FIND($A$2,Lines!E17))-FIND($A$2,Lines!E17)-LEN($A$2)-1)) | F17: =IF(ISERROR(FIND($A$2,Lines!F17))=TRUE,"",MID(Lines!F17,FIND($A$2,Lines!F17)+LEN($A$2)+1,FIND(",",_xlfn.CONCAT(Lines!F17,","),FIND($A$2,Lines!F17))-FIND($A$2,Lines!F17)-LEN($A$2)-1)) | G17: =IF(ISERROR(FIND($A$2,Lines!G17))=TRUE,"",MID(Lines!G17,FIND($A$2,Lines!G17)+LEN($A$2)+1,FIND(",",_xlfn.CONCAT(Lines!G17,","),FIND($A$2,Lines!G17))-FIND($A$2,Lines!G17)-LEN($A$2)-1)) | H17: =IF(ISERROR(FIND($A$2,Lines!H17))=TRUE,"",MID(Lines!H17,FIND($A$2,Lines!H17)+LEN($A$2)+1,FIND(",",_xlfn.CONCAT(Lines!H17,","),FIND($A$2,Lines!H17))-FIND($A$2,Lines!H17)-LEN($A$2)-1)) | I17: =IF(ISERROR(FIND($A$2,Lines!I17))=TRUE,"",MID(Lines!I17,FIND($A$2,Lines!I17)+LEN($A$2)+1,FIND(",",_xlfn.CONCAT(Lines!I17,","),FIND($A$2,Lines!I17))-FIND($A$2,Lines!I17)-LEN($A$2)-1)) | ... Z17: =IF(ISERROR(FIND($A$2,Lines!Z17))=TRUE,"",MID(Lines!Z17,FIND($A$2,Lines!Z17)+LEN($A$2)+1,FIND(",",_xlfn.CONCAT(Lines!Z17,","),FIND($A$2,Lines!Z17))-FIND($A$2,Lines!Z17)-LEN($A$2)-1)) | AA17: =IF(ISERROR(FIND($A$2,Lines!AB16))=TRUE,"",MID(Lines!AB16,FIND($A$2,Lines!AB16)+LEN($A$2)+1,FIND(",",_xlfn.CONCAT(Lines!AB16,","),FIND($A$2,Lines!AB16))-FIND($A$2,Lines!AB16)-LEN($A$2)-1)) | AB17: =IF(ISERROR(FIND($A$2,Lines!AB17))=TRUE,"",MID(Lines!AB17,FIND($A$2,Lines!AB17)+LEN($A$2)+1,FIND(",",_xlfn.CONCAT(Lines!AB17,","),FIND($A$2,Lines!AB17))-FIND($A$2,Lines!AB17)-LEN($A$2)-1)) | AC17: =IF(ISERROR(FIND($A$2,Lines!AC17))=TRUE,"",MID(Lines!AC17,FIND($A$2,Lines!AC17)+LEN($A$2)+1,FIND(",",_xlfn.CONCAT(Lines!AC17,","),FIND($A$2,Lines!AC17))-FIND($A$2,Lines!AC17)-LEN($A$2)-1)) | AD17: =IF(ISERROR(FIND($A$2,Lines!AD17))=TRUE,"",MID(Lines!AD17,FIND($A$2,Lines!AD17)+LEN($A$2)+1,FIND(",",_xlfn.CONCAT(Lines!AD17,","),FIND($A$2,Lines!AD17))-FIND($A$2,Lines!AD17)-LEN($A$2)-1)) | AE17: =IF(ISERROR(FIND($A$2,Lines!AE17))=TRUE,"",MID(Lines!AE17,FIND($A$2,Lines!AE17)+LEN($A$2)+1,FIND(",",_xlfn.CONCAT(Lines!AE17,","),FIND($A$2,Lines!AE17))-FIND($A$2,Lines!AE17)-LEN($A$2)-1)) | AF17: =IF(ISERROR(FIND($A$2,Lines!AF17))=TRUE,"",MID(Lines!AF17,FIND($A$2,Lines!AF17)+LEN($A$2)+1,FIND(",",_xlfn.CONCAT(Lines!AF17,","),FIND($A$2,Lines!AF17))-FIND($A$2,Lines!AF17)-LEN($A$2)-1)) | AG17: =IF(ISERROR(FIND($A$2,Lines!AG17))=TRUE,"",MID(Lines!AG17,FIND($A$2,Lines!AG17)+LEN($A$2)+1,FIND(",",_xlfn.CONCAT(Lines!AG17,","),FIND($A$2,Lines!AG17))-FIND($A$2,Lines!AG17)-LEN($A$2)-1)) | AH17: =IF(ISERROR(FIND($A$2,Lines!AH17))=TRUE,"",MID(Lines!AH17,FIND($A$2,Lines!AH17)+LEN($A$2)+1,FIND(",",_xlfn.CONCAT(Lines!AH17,","),FIND($A$2,Lines!AH17))-FIND($A$2,Lines!AH17)-LEN($A$2)-1)) | AI17: =IF(ISERROR(FIND($A$2,Lines!AI17))=TRUE,"",MID(Lines!AI17,FIND($A$2,Lines!AI17)+LEN($A$2)+1,FIND(",",_xlfn.CONCAT(Lines!AI17,","),FIND($A$2,Lines!AI17))-FIND($A$2,Lines!AI17)-LEN($A$2)-1)) | ... AT17: =IF(ISERROR(FIND($A$2,Lines!AT17))=TRUE,"",MID(Lines!AT17,FIND($A$2,Lines!AT17)+LEN($A$2)+1,FIND(",",_xlfn.CONCAT(Lines!AT17,","),FIND($A$2,Lines!AT17))-FIND($A$2,Lines!AT17)-LEN($A$2)-1))
A18: 甘肃西 | B18: =IF(ISERROR(FIND($A$2,Lines!B18))=TRUE,"",MID(Lines!B18,FIND($A$2,Lines!B18)+LEN($A$2)+1,FIND(",",_xlfn.CONCAT(Lines!B18,","),FIND($A$2,Lines!B18))-FIND($A$2,Lines!B18)-LEN($A$2)-1)) | C18: =IF(ISERROR(FIND($A$2,Lines!C18))=TRUE,"",MID(Lines!C18,FIND($A$2,Lines!C18)+LEN($A$2)+1,FIND(",",_xlfn.CONCAT(Lines!C18,","),FIND($A$2,Lines!C18))-FIND($A$2,Lines!C18)-LEN($A$2)-1)) | D18: =IF(ISERROR(FIND($A$2,Lines!D18))=TRUE,"",MID(Lines!D18,FIND($A$2,Lines!D18)+LEN($A$2)+1,FIND(",",_xlfn.CONCAT(Lines!D18,","),FIND($A$2,Lines!D18))-FIND($A$2,Lines!D18)-LEN($A$2)-1)) | E18: =IF(ISERROR(FIND($A$2,Lines!E18))=TRUE,"",MID(Lines!E18,FIND($A$2,Lines!E18)+LEN($A$2)+1,FIND(",",_xlfn.CONCAT(Lines!E18,","),FIND($A$2,Lines!E18))-FIND($A$2,Lines!E18)-LEN($A$2)-1)) | F18: =IF(ISERROR(FIND($A$2,Lines!F18))=TRUE,"",MID(Lines!F18,FIND($A$2,Lines!F18)+LEN($A$2)+1,FIND(",",_xlfn.CONCAT(Lines!F18,","),FIND($A$2,Lines!F18))-FIND($A$2,Lines!F18)-LEN($A$2)-1)) | G18: =IF(ISERROR(FIND($A$2,Lines!G18))=TRUE,"",MID(Lines!G18,FIND($A$2,Lines!G18)+LEN($A$2)+1,FIND(",",_xlfn.CONCAT(Lines!G18,","),FIND($A$2,Lines!G18))-FIND($A$2,Lines!G18)-LEN($A$2)-1)) | H18: =IF(ISERROR(FIND($A$2,Lines!H18))=TRUE,"",MID(Lines!H18,FIND($A$2,Lines!H18)+LEN($A$2)+1,FIND(",",_xlfn.CONCAT(Lines!H18,","),FIND($A$2,Lines!H18))-FIND($A$2,Lines!H18)-LEN($A$2)-1)) | I18: =IF(ISERROR(FIND($A$2,Lines!I18))=TRUE,"",MID(Lines!I18,FIND($A$2,Lines!I18)+LEN($A$2)+1,FIND(",",_xlfn.CONCAT(Lines!I18,","),FIND($A$2,Lines!I18))-FIND($A$2,Lines!I18)-LEN($A$2)-1)) | ... AT18: =IF(ISERROR(FIND($A$2,Lines!AT18))=TRUE,"",MID(Lines!AT18,FIND($A$2,Lines!AT18)+LEN($A$2)+1,FIND(",",_xlfn.CONCAT(Lines!AT18,","),FIND($A$2,Lines!AT18))-FIND($A$2,Lines!AT18)-LEN($A$2)-1))
A19: 甘肃中 | B19: =IF(ISERROR(FIND($A$2,Lines!B19))=TRUE,"",MID(Lines!B19,FIND($A$2,Lines!B19)+LEN($A$2)+1,FIND(",",_xlfn.CONCAT(Lines!B19,","),FIND($A$2,Lines!B19))-FIND($A$2,Lines!B19)-LEN($A$2)-1)) | C19: =IF(ISERROR(FIND($A$2,Lines!C19))=TRUE,"",MID(Lines!C19,FIND($A$2,Lines!C19)+LEN($A$2)+1,FIND(",",_xlfn.CONCAT(Lines!C19,","),FIND($A$2,Lines!C19))-FIND($A$2,Lines!C19)-LEN($A$2)-1)) | D19: =IF(ISERROR(FIND($A$2,Lines!D19))=TRUE,"",MID(Lines!D19,FIND($A$2,Lines!D19)+LEN($A$2)+1,FIND(",",_xlfn.CONCAT(Lines!D19,","),FIND($A$2,Lines!D19))-FIND($A$2,Lines!D19)-LEN($A$2)-1)) | E19: =IF(ISERROR(FIND($A$2,Lines!E19))=TRUE,"",MID(Lines!E19,FIND($A$2,Lines!E19)+LEN($A$2)+1,FIND(",",_xlfn.CONCAT(Lines!E19,","),FIND($A$2,Lines!E19))-FIND($A$2,Lines!E19)-LEN($A$2)-1)) | F19: =IF(ISERROR(FIND($A$2,Lines!F19))=TRUE,"",MID(Lines!F19,FIND($A$2,Lines!F19)+LEN($A$2)+1,FIND(",",_xlfn.CONCAT(Lines!F19,","),FIND($A$2,Lines!F19))-FIND($A$2,Lines!F19)-LEN($A$2)-1)) | G19: =IF(ISERROR(FIND($A$2,Lines!G19))=TRUE,"",MID(Lines!G19,FIND($A$2,Lines!G19)+LEN($A$2)+1,FIND(",",_xlfn.CONCAT(Lines!G19,","),FIND($A$2,Lines!G19))-FIND($A$2,Lines!G19)-LEN($A$2)-1)) | H19: =IF(ISERROR(FIND($A$2,Lines!H19))=TRUE,"",MID(Lines!H19,FIND($A$2,Lines!H19)+LEN($A$2)+1,FIND(",",_xlfn.CONCAT(Lines!H19,","),FIND($A$2,Lines!H19))-FIND($A$2,Lines!H19)-LEN($A$2)-1)) | I19: =IF(ISERROR(FIND($A$2,Lines!I19))=TRUE,"",MID(Lines!I19,FIND($A$2,Lines!I19)+LEN($A$2)+1,FIND(",",_xlfn.CONCAT(Lines!I19,","),FIND($A$2,Lines!I19))-FIND($A$2,Lines!I19)-LEN($A$2)-1)) | ... AT19: =IF(ISERROR(FIND($A$2,Lines!AT19))=TRUE,"",MID(Lines!AT19,FIND($A$2,Lines!AT19)+LEN($A$2)+1,FIND(",",_xlfn.CONCAT(Lines!AT19,","),FIND($A$2,Lines!AT19))-FIND($A$2,Lines!AT19)-LEN($A$2)-1))
A20: 甘肃南 | B20: =IF(ISERROR(FIND($A$2,Lines!B20))=TRUE,"",MID(Lines!B20,FIND($A$2,Lines!B20)+LEN($A$2)+1,FIND(",",_xlfn.CONCAT(Lines!B20,","),FIND($A$2,Lines!B20))-FIND($A$2,Lines!B20)-LEN($A$2)-1)) | C20: =IF(ISERROR(FIND($A$2,Lines!C20))=TRUE,"",MID(Lines!C20,FIND($A$2,Lines!C20)+LEN($A$2)+1,FIND(",",_xlfn.CONCAT(Lines!C20,","),FIND($A$2,Lines!C20))-FIND($A$2,Lines!C20)-LEN($A$2)-1)) | D20: =IF(ISERROR(FIND($A$2,Lines!D20))=TRUE,"",MID(Lines!D20,FIND($A$2,Lines!D20)+LEN($A$2)+1,FIND(",",_xlfn.CONCAT(Lines!D20,","),FIND($A$2,Lines!D20))-FIND($A$2,Lines!D20)-LEN($A$2)-1)) | E20: =IF(ISERROR(FIND($A$2,Lines!E20))=TRUE,"",MID(Lines!E20,FIND($A$2,Lines!E20)+LEN($A$2)+1,FIND(",",_xlfn.CONCAT(Lines!E20,","),FIND($A$2,Lines!E20))-FIND($A$2,Lines!E20)-LEN($A$2)-1)) | F20: =IF(ISERROR(FIND($A$2,Lines!F20))=TRUE,"",MID(Lines!F20,FIND($A$2,Lines!F20)+LEN($A$2)+1,FIND(",",_xlfn.CONCAT(Lines!F20,","),FIND($A$2,Lines!F20))-FIND($A$2,Lines!F20)-LEN($A$2)-1)) | G20: =IF(ISERROR(FIND($A$2,Lines!G20))=TRUE,"",MID(Lines!G20,FIND($A$2,Lines!G20)+LEN($A$2)+1,FIND(",",_xlfn.CONCAT(Lines!G20,","),FIND($A$2,Lines!G20))-FIND($A$2,Lines!G20)-LEN($A$2)-1)) | H20: =IF(ISERROR(FIND($A$2,Lines!H20))=TRUE,"",MID(Lines!H20,FIND($A$2,Lines!H20)+LEN($A$2)+1,FIND(",",_xlfn.CONCAT(Lines!H20,","),FIND($A$2,Lines!H20))-FIND($A$2,Lines!H20)-LEN($A$2)-1)) | I20: =IF(ISERROR(FIND($A$2,Lines!I20))=TRUE,"",MID(Lines!I20,FIND($A$2,Lines!I20)+LEN($A$2)+1,FIND(",",_xlfn.CONCAT(Lines!I20,","),FIND($A$2,Lines!I20))-FIND($A$2,Lines!I20)-LEN($A$2)-1)) | ... AT20: =IF(ISERROR(FIND($A$2,Lines!AT20))=TRUE,"",MID(Lines!AT20,FIND($A$2,Lines!AT20)+LEN($A$2)+1,FIND(",",_xlfn.CONCAT(Lines!AT20,","),FIND($A$2,Lines!AT20))-FIND($A$2,Lines!AT20)-LEN($A$2)-1))
A21: 青海 | B21: =IF(ISERROR(FIND($A$2,Lines!B21))=TRUE,"",MID(Lines!B21,FIND($A$2,Lines!B21)+LEN($A$2)+1,FIND(",",_xlfn.CONCAT(Lines!B21,","),FIND($A$2,Lines!B21))-FIND($A$2,Lines!B21)-LEN($A$2)-1)) | C21: =IF(ISERROR(FIND($A$2,Lines!C21))=TRUE,"",MID(Lines!C21,FIND($A$2,Lines!C21)+LEN($A$2)+1,FIND(",",_xlfn.CONCAT(Lines!C21,","),FIND($A$2,Lines!C21))-FIND($A$2,Lines!C21)-LEN($A$2)-1)) | D21: =IF(ISERROR(FIND($A$2,Lines!D21))=TRUE,"",MID(Lines!D21,FIND($A$2,Lines!D21)+LEN($A$2)+1,FIND(",",_xlfn.CONCAT(Lines!D21,","),FIND($A$2,Lines!D21))-FIND($A$2,Lines!D21)-LEN($A$2)-1)) | E21: =IF(ISERROR(FIND($A$2,Lines!E21))=TRUE,"",MID(Lines!E21,FIND($A$2,Lines!E21)+LEN($A$2)+1,FIND(",",_xlfn.CONCAT(Lines!E21,","),FIND($A$2,Lines!E21))-FIND($A$2,Lines!E21)-LEN($A$2)-1)) | F21: =IF(ISERROR(FIND($A$2,Lines!F21))=TRUE,"",MID(Lines!F21,FIND($A$2,Lines!F21)+LEN($A$2)+1,FIND(",",_xlfn.CONCAT(Lines!F21,","),FIND($A$2,Lines!F21))-FIND($A$2,Lines!F21)-LEN($A$2)-1)) | G21: =IF(ISERROR(FIND($A$2,Lines!G21))=TRUE,"",MID(Lines!G21,FIND($A$2,Lines!G21)+LEN($A$2)+1,FIND(",",_xlfn.CONCAT(Lines!G21,","),FIND($A$2,Lines!G21))-FIND($A$2,Lines!G21)-LEN($A$2)-1)) | H21: =IF(ISERROR(FIND($A$2,Lines!H21))=TRUE,"",MID(Lines!H21,FIND($A$2,Lines!H21)+LEN($A$2)+1,FIND(",",_xlfn.CONCAT(Lines!H21,","),FIND($A$2,Lines!H21))-FIND($A$2,Lines!H21)-LEN($A$2)-1)) | I21: =IF(ISERROR(FIND($A$2,Lines!I21))=TRUE,"",MID(Lines!I21,FIND($A$2,Lines!I21)+LEN($A$2)+1,FIND(",",_xlfn.CONCAT(Lines!I21,","),FIND($A$2,Lines!I21))-FIND($A$2,Lines!I21)-LEN($A$2)-1)) | ... AT21: =IF(ISERROR(FIND($A$2,Lines!AT21))=TRUE,"",MID(Lines!AT21,FIND($A$2,Lines!AT21)+LEN($A$2)+1,FIND(",",_xlfn.CONCAT(Lines!AT21,","),FIND($A$2,Lines!AT21))-FIND($A$2,Lines!AT21)-LEN($A$2)-1))
A22: 宁夏自治区 | B22: =IF(ISERROR(FIND($A$2,Lines!B22))=TRUE,"",MID(Lines!B22,FIND($A$2,Lines!B22)+LEN($A$2)+1,FIND(",",_xlfn.CONCAT(Lines!B22,","),FIND($A$2,Lines!B22))-FIND($A$2,Lines!B22)-LEN($A$2)-1)) | C22: =IF(ISERROR(FIND($A$2,Lines!C22))=TRUE,"",MID(Lines!C22,FIND($A$2,Lines!C22)+LEN($A$2)+1,FIND(",",_xlfn.CONCAT(Lines!C22,","),FIND($A$2,Lines!C22))-FIND($A$2,Lines!C22)-LEN($A$2)-1)) | D22: =IF(ISERROR(FIND($A$2,Lines!D22))=TRUE,"",MID(Lines!D22,FIND($A$2,Lines!D22)+LEN($A$2)+1,FIND(",",_xlfn.CONCAT(Lines!D22,","),FIND($A$2,Lines!D22))-FIND($A$2,Lines!D22)-LEN($A$2)-1)) | E22: =IF(ISERROR(FIND($A$2,Lines!E22))=TRUE,"",MID(Lines!E22,FIND($A$2,Lines!E22)+LEN($A$2)+1,FIND(",",_xlfn.CONCAT(Lines!E22,","),FIND($A$2,Lines!E22))-FIND($A$2,Lines!E22)-LEN($A$2)-1)) | F22: =IF(ISERROR(FIND($A$2,Lines!F22))=TRUE,"",MID(Lines!F22,FIND($A$2,Lines!F22)+LEN($A$2)+1,FIND(",",_xlfn.CONCAT(Lines!F22,","),FIND($A$2,Lines!F22))-FIND($A$2,Lines!F22)-LEN($A$2)-1)) | G22: =IF(ISERROR(FIND($A$2,Lines!G22))=TRUE,"",MID(Lines!G22,FIND($A$2,Lines!G22)+LEN($A$2)+1,FIND(",",_xlfn.CONCAT(Lines!G22,","),FIND($A$2,Lines!G22))-FIND($A$2,Lines!G22)-LEN($A$2)-1)) | H22: =IF(ISERROR(FIND($A$2,Lines!H22))=TRUE,"",MID(Lines!H22,FIND($A$2,Lines!H22)+LEN($A$2)+1,FIND(",",_xlfn.CONCAT(Lines!H22,","),FIND($A$2,Lines!H22))-FIND($A$2,Lines!H22)-LEN($A$2)-1)) | I22: =IF(ISERROR(FIND($A$2,Lines!I22))=TRUE,"",MID(Lines!I22,FIND($A$2,Lines!I22)+LEN($A$2)+1,FIND(",",_xlfn.CONCAT(Lines!I22,","),FIND($A$2,Lines!I22))-FIND($A$2,Lines!I22)-LEN($A$2)-1)) | ... AT22: =IF(ISERROR(FIND($A$2,Lines!AT22))=TRUE,"",MID(Lines!AT22,FIND($A$2,Lines!AT22)+LEN($A$2)+1,FIND(",",_xlfn.CONCAT(Lines!AT22,","),FIND($A$2,Lines!AT22))-FIND($A$2,Lines!AT22)-LEN($A$2)-1))
